Workbook

Sheet Calculation
A1: Package Name | C1: Duration (Days) | D1: No of Pax
A2: 3 Day Bromo, Madakaripura Waterfall & Ijen Overland from Surabaya to Bali | C2: 3 | D2: 1
A4: Description | B4: Unit | C4: Rate | D4: Qty | E4: Total
A5: A. Accommodation
A6: A1. Ijen
A7: Riverside Homestay - Deluxe | B7: No | C7: 337500 | D7: =ROUNDUP(D2/2,0) -> 1 | E7: =C7*D7 -> 337500
A8: Riverside Homestay - Executive | B8: No | C8: 375000 | E8: =C8*D8 -> 0
A9: Riverside Homestay - Emerald | B9: No | C9: 412500 | E9: =C9*D9 -> 0
A10: Riverside Homestay - Platinum | B10: No | C10: 487500 | E10: =C10*D10 -> 0
A11: Riverside Homestay - Family | B11: No | C11: 562500 | E11: =C11*D11 -> 0
A12: A2. Bromo
A13: Joglo Kecombrang - Deluxe | B13: No | C13: 750000 | D13: =ROUNDUP(D2/2,0) -> 1 | E13: =C13*D13 -> 750000
A14: Joglo Kecombrang - Family | B14: No | C14: 950000 | E14: =C14*D14 -> 0
A15: Joglo Kecombrang - Extra Bed | B15: No | C15: 300000 | E15: =C15*D15 -> 0
A16: B. Activities | E16: =C16*D16 -> 0
A17: B1. Ijen | E17: =C17*D17 -> 0
A18: Ijen - Ticket | B18: Pax | C18: 75000 | D18: =D2 -> 1 | E18: =C18*D18 -> 75000
A19: Medical Check up | B19: Pax | C19: 35000 | E19: =C19*D19 -> 0
A20: Coffee + Indo Mee | B20: Pax | C20: 25000 | D20: =D2 -> 1 | E20: =C20*D20 -> 25000
A21: Ijen Local Guide | B21: No | C21: 250000 | D21: 1 | E21: =C21*D21 -> 250000
A22: Riverside - Lunch | B22: Pax | C22: 65000 | E22: =C22*D22 -> 0
A23: Riverside - Dinner | B23: Pax | C23: 65000 | D23: =D2 -> 1 | E23: =C23*D23 -> 65000
A24: Baratha - Lunch | B24: Pax | C24: 60000 | E24: =C24*D24 -> 0
A25: Baratha - Dinner | B25: Pax | C25: 60000 | E25: =C25*D25 -> 0
A26: Ijen Certificate | B26: No | C26: 35000 | E26: =C26*D26 -> 0
A27: B2. Bromo
A28: Bromo - Ticket | B28: Pax | C28: 160000 | D28: =D2 -> 1 | E28: =C28*D28 -> 160000
A29: Bromo - Jeep | B29: Pax | C29: 500000 | D29: =ROUNDUP(D2/4,0) -> 1 | E29: =C29*D29 -> 500000
A30: B3. Madakaripura
A31: Motor + Ticket | B31: Pax | C31: 90000 | D31: =D2 -> 1 | E31: =C31*D31 -> 90000
A32: Madakaripura Local Guide | B32: No | C32: 100000 | D32: 1 | E32: =C32*D32 -> 100000
A33: C. Transportation
A34: C1. Vehicle
A35: Avanza | B35: Day x Qty | C35: 450000 | D35: =IF($D$2=1,$C$2, IF($D$2=2,$C$2,0)) -> 3 | E35: =C35*D35 -> 1350000
A36: Innova | B36: Day x Qty | C36: 550000 | D36: =IF($D$2=3,$C$2, 0) -> 0 | E36: =C36*D36 -> 0
A37: Toyota Hiace | B37: Day x Qty | C37: 1100000 | D37: =IF((($D$2>=4)*($D$2<=11))=1,$C$2,0) -> 0 | E37: =C37*D37 -> 0
A38: Toyota Hiace Premio (4-6pax) | B38: Day x Qty | C38: 1300000 | E38: =C38*D38 -> 0
A39: Extra Luggage | B39: Day x Qty | C39: =250000+200000+200000 -> 650000 | D39: 0 | E39: =C39*D39 -> 0
A40: C2. Parking and toll
A41: Probolingo | B41: No | C41: 200000 | D41: =IF((($D$2>=10)*($D$2<=11))=1,2,1) -> 1 | E41: =C41*D41 -> 200000
...

Sheet Summary
A1: Package Name | G1: Duration (Days)
A2: 3 Day Bromo, Madakaripura Waterfall & Ijen Overland from Surabaya to Bali | G2: 3
A4: Pax | B4: Expense / Pax | C4: Total Expense | D4: Harga / Pax | E4: Total Harga | F4: Margin | G4: Presentase Margin
A5: 1 | B5: ='1 Pax'!E39 -> 4913500 | C5: =B5*A5 -> 4913500 | D5: 6300000 | E5: =D5*A5 -> 6300000 | F5: =E5-C5 -> 1386500 | G5: =F5/E5*100 -> 22.007937
A6: 2 | B6: ='2 Pax'!E39 -> 2719750 | C6: =B6*A6 -> 5439500 | D6: 3570000 | E6: =D6*A6 -> 7140000 | F6: =E6-C6 -> 1700500 | G6: =F6/E6*100 -> 23.816527
A7: 3 | B7: ='3 Pax'!E39 -> 2146833.3 | C7: =B7*A7 -> 6440500 | D7: 3275000 | E7: =D7*A7 -> 9825000 | F7: =E7-C7 -> 3384500 | G7: =F7/E7*100 -> 34.447837
A8: 4 | B8: ='4 Pax'!E38 -> 2332250 | C8: =B8*A8 -> 9329000 | D8: 3050000 | E8: =D8*A8 -> 12200000 | F8: =E8-C8 -> 2871000 | G8: =F8/E8*100 -> 23.532787
A9: 5 | B9: ='5 Pax'!E41 -> 2206000 | C9: =B9*A9 -> 11030000 | D9: 3050000 | E9: =D9*A9 -> 15250000 | F9: =E9-C9 -> 4220000 | G9: =F9/E9*100 -> 27.672131
A10: 6 | B10: ='6 Pax'!E39 -> 2044750 | C10: =B10*A10 -> 12268500 | D10: 2850000 | E10: =D10*A10 -> 17100000 | F10: =E10-C10 -> 4831500 | G10: =F10/E10*100 -> 28.254386
A11: 7 | B11: ='7 Pax'!E41 -> 1888500 | C11: =B11*A11 -> 13219500 | D11: 2850000 | E11: =D11*A11 -> 19950000 | F11: =E11-C11 -> 6730500 | G11: =F11/E11*100 -> 33.736842
A12: 8 | B12: ='8 Pax'!E39 -> 1801000 | C12: =B12*A12 -> 14408000 | D12: 2550000 | E12: =D12*A12 -> 20400000 | F12: =E12-C12 -> 5992000 | G12: =F12/E12*100 -> 29.372549
A13: 9 | B13: ='9 Pax'!E41 -> 1767666.7 | C13: =B13*A13 -> 15909000 | D13: 2550000 | E13: =D13*A13 -> 22950000 | F13: =E13-C13 -> 7041000 | G13: =F13/E13*100 -> 30.679739
A14: 10 | B14: ='10 Pax'!E40 -> 1924750 | C14: =B14*A14 -> 19247500 | D14: 2550000 | E14: =D14*A14 -> 25500000 | F14: =E14-C14 -> 6252500 | G14: =F14/E14*100 -> 24.519608
A15: 11 | B15: ='11 Pax'!E42 -> 1840772.7 | C15: =B15*A15 -> 20248500 | D15: 2450000 | E15: =D15*A15 -> 26950000 | F15: =E15-C15 -> 6701500 | G15: =F15/E15*100 -> 24.866419

Sheet 1 Pax
A1: Package Name | C1: Duration (Days) | D1: No of Pax | E1: Price Per Pax
A2: 3 Day Bromo, Madakaripura Waterfall & Ijen Overland from Surabaya to Bali | C2: 3 | D2: 1 | E2: 6300000
A4: Description | B4: Unit | C4: Rate | D4: Qty | E4: Total
A5: A. Accommodation
A6: A1. Ijen
A7: Riverside Homestay - Deluxe | B7: No | C7: 337500 | D7: =ROUNDUP(D2/2,0) -> 1 | E7: =C7*D7 -> 337500
A8: A2. Bromo
A9: Joglo Kecombrang - Deluxe | B9: No | C9: 750000 | D9: =ROUNDUP(D2/2,0) -> 1 | E9: =C9*D9 -> 750000
A10: B. Activities | E10: =C10*D10 -> 0
A11: B1. Ijen | E11: =C11*D11 -> 0
A12: Ijen - Ticket | B12: Pax | C12: 75000 | D12: =D2 -> 1 | E12: =C12*D12 -> 75000
A13: Medical Check up | B13: Pax | C13: 35000 | D13: =D2 -> 1 | E13: =C13*D13 -> 35000
A14: Coffee + Indo Mee | B14: Pax | C14: 25000 | D14: =D2 -> 1 | E14: =C14*D14 -> 25000
A15: Ijen Local Guide | B15: No | C15: 250000 | D15: 1 | E15: =C15*D15 -> 250000
A16: Riverside - Dinner | B16: Pax | C16: 65000 | D16: =D2 -> 1 | E16: =C16*D16 -> 65000
A17: B2. Bromo
A18: Bromo - Ticket | B18: Pax | C18: 160000 | D18: =D2 -> 1 | E18: =C18*D18 -> 160000
A19: Bromo - Jeep | B19: Pax | C19: 500000 | D19: =ROUNDUP(D2/4,0) -> 1 | E19: =C19*D19 -> 500000
A20: B3. Madakaripura
A21: Motor + Ticket | B21: Pax | C21: 90000 | D21: =D2 -> 1 | E21: =C21*D21 -> 90000
A22: Madakaripura Local Guide | B22: No | C22: 100000 | D22: 1 | E22: =C22*D22 -> 100000
A23: C. Transportation
A24: C1. Vehicle
A25: Avanza | B25: Day x Qty | C25: 450000 | D25: =IF($D$2=1,$C$2, IF($D$2=2,$C$2,0)) -> 3 | E25: =C25*D25 -> 1350000
A26: C2. Parking and toll
A27: Probolingo | B27: No | C27: 200000 | D27: =IF((($D$2>=10)*($D$2<=11))=1,2,1) -> 1 | E27: =C27*D27 -> 200000
A28: D. Crews | E28: =C28*D28 -> 0
A29: D1. In house | E29: =C29*D29 -> 0
A30: Driver cum guide | B30: Day x Qty | C30: 250000 | D30: =IF((($D$2>=1)*($D$2<=3))=1,$C$2,0) -> 3 | E30: =C30*D30 -> 750000
A31: E. Others | E31: =C31*D31 -> 0
A32: E1. Miscelleneous | E32: =C32*D32 -> 0
A33: Mineral Water | B33: Karton | C33: 50000 | D33: =ROUNDUP(D2*C2*3/24,0) -> 1 | E33: =C33*D33 -> 50000
A34: Transport allowance | B34: Day x Qty | C34: 100000 | D34: 1 | E34: =C34*D34 -> 100000
A35: T Shirt | B35: Pax | C35: 60000 | D35: =D2 -> 1 | E35: =C35*D35 -> 60000
A36: E3. Bali Transfer | E36: =C36*D36 -> 0
A37: Ferry tickets (1-way) | B37: Pax | C37: 16000 | D37: =D2 -> 1 | E37: =C37*D37 -> 16000
A38: Total Expense | E38: =SUM(E7:E37) -> 4913500
A39: Expense / Pax | E39: =E38/D2 -> 4913500

Sheet 2 Pax
A1: \ | C1: Duration (Days) | D1: No of Pax | E1: Price Per Pax
A2: 3 Day Bromo, Madakaripura Waterfall & Ijen Overland from Surabaya to Bali | C2: 3 | D2: 2 | E2: 3570000
A4: Description | B4: Unit | C4: Rate | D4: Qty | E4: Total
A5: A. Accommodation
A6: A1. Ijen
A7: Riverside Homestay - Deluxe | B7: No | C7: 337500 | D7: =ROUNDUP(D2/2,0) -> 1 | E7: =C7*D7 -> 337500
A8: A2. Bromo
A9: Joglo Kecombrang - Deluxe | B9: No | C9: 750000 | D9: =ROUNDUP(D2/2,0) -> 1 | E9: =C9*D9 -> 750000
A10: B. Activities | E10: =C10*D10 -> 0
A11: B1. Ijen | E11: =C11*D11 -> 0
A12: Ijen - Ticket | B12: Pax | C12: 75000 | D12: =D2 -> 2 | E12: =C12*D12 -> 150000
A13: Medical Check up | B13: Pax | C13: 35000 | D13: =D2 -> 2 | E13: =C13*D13 -> 70000
A14: Coffee + Indo Mee | B14: Pax | C14: 25000 | D14: =D2 -> 2 | E14: =C14*D14 -> 50000
A15: Ijen Local Guide | B15: No | C15: 250000 | D15: 1 | E15: =C15*D15 -> 250000
A16: Riverside - Dinner | B16: Pax | C16: 65000 | D16: =D2 -> 2 | E16: =C16*D16 -> 130000
A17: B2. Bromo
A18: Bromo - Ticket | B18: Pax | C18: 160000 | D18: =D2 -> 2 | E18: =C18*D18 -> 320000
A19: Bromo - Jeep | B19: Pax | C19: 500000 | D19: =ROUNDUP(D2/4,0) -> 1 | E19: =C19*D19 -> 500000
A20: B3. Madakaripura
A21: Motor + Ticket | B21: Pax | C21: 90000 | D21: =D2 -> 2 | E21: =C21*D21 -> 180000
A22: Madakaripura Local Guide | B22: No | C22: 100000 | D22: 1 | E22: =C22*D22 -> 100000
A23: C. Transportation
A24: C1. Vehicle
A25: Avanza | B25: Day x Qty | C25: 450000 | D25: =IF($D$2=1,$C$2, IF($D$2=2,$C$2,0)) -> 3 | E25: =C25*D25 -> 1350000
A26: C2. Parking and toll
A27: Probolingo | B27: No | C27: 200000 | D27: =IF((($D$2>=10)*($D$2<=11))=1,2,1) -> 1 | E27: =C27*D27 -> 200000
A28: D. Crews | E28: =C28*D28 -> 0
A29: D1. In house | E29: =C29*D29 -> 0
A30: Driver cum guide | B30: Day x Qty | C30: 250000 | D30: =IF((($D$2>=1)*($D$2<=3))=1,$C$2,0) -> 3 | E30: =C30*D30 -> 750000
A31: E. Others | E31: =C31*D31 -> 0
A32: E1. Miscelleneous | E32: =C32*D32 -> 0
A33: Mineral Water | B33: Karton | C33: 50000 | D33: =ROUNDUP(D2*C2*3/24,0) -> 1 | E33: =C33*D33 -> 50000
A34: Transport allowance | B34: Day x Qty | C34: 100000 | D34: 1 | E34: =C34*D34 -> 100000
A35: T Shirt | B35: Pax | C35: 60000 | D35: =D2 -> 2 | E35: =C35*D35 -> 120000
A36: E3. Bali Transfer | E36: =C36*D36 -> 0
A37: Ferry tickets (1-way) | B37: Pax | C37: 16000 | D37: =D2 -> 2 | E37: =C37*D37 -> 32000
A38: Total Expense | E38: =SUM(E7:E37) -> 5439500
A39: Expense / Pax | E39: =E38/D2 -> 2719750

Sheet 3 Pax
A1: Package Name | C1: Duration (Days) | D1: No of Pax | E1: Price Per Pax
A2: 3 Day Bromo, Madakaripura Waterfall & Ijen Overland from Surabaya to Bali | C2: 3 | D2: 3 | E2: 3275000
A4: Description | B4: Unit | C4: Rate | D4: Qty | E4: Total
A5: A. Accommodation
A6: A1. Ijen
A7: Riverside Homestay - Family | B7: No | C7: 562500 | D7: 1 | E7: =C7*D7 -> 562500
A8: A2. Bromo
A9: Joglo Kecombrang - Family | B9: No | C9: 950000 | D9: 1 | E9: =C9*D9 -> 950000
A10: B. Activities | E10: =C10*D10 -> 0
A11: B1. Ijen | E11: =C11*D11 -> 0
A12: Ijen - Ticket | B12: Pax | C12: 75000 | D12: =D2 -> 3 | E12: =C12*D12 -> 225000
A13: Medical Check up | B13: Pax | C13: 35000 | D13: =D2 -> 3 | E13: =C13*D13 -> 105000
A14: Coffee + Indo Mee | B14: Pax | C14: 25000 | D14: =D2 -> 3 | E14: =C14*D14 -> 75000
A15: Ijen Local Guide | B15: No | C15: 250000 | D15: 1 | E15: =C15*D15 -> 250000
A16: Riverside - Dinner | B16: Pax | C16: 65000 | D16: =D2 -> 3 | E16: =C16*D16 -> 195000
A17: B2. Bromo
A18: Bromo - Ticket | B18: Pax | C18: 160000 | D18: =D2 -> 3 | E18: =C18*D18 -> 480000
A19: Bromo - Jeep | B19: Pax | C19: 500000 | D19: =ROUNDUP(D2/4,0) -> 1 | E19: =C19*D19 -> 500000
A20: B3. Madakaripura
A21: Motor + Ticket | B21: Pax | C21: 90000 | D21: =D2 -> 3 | E21: =C21*D21 -> 270000
A22: Madakaripura Local Guide | B22: No | C22: 100000 | D22: 1 | E22: =C22*D22 -> 100000
A23: C. Transportation
A24: C1. Vehicle
A25: Avanza | B25: Day x Qty | C25: 450000 | D25: 3 | E25: =C25*D25 -> 1350000
A26: C2. Parking and toll
A27: Probolingo | B27: No | C27: 200000 | D27: =IF((($D$2>=10)*($D$2<=11))=1,2,1) -> 1 | E27: =C27*D27 -> 200000
A28: D. Crews | E28: =C28*D28 -> 0
A29: D1. In house | E29: =C29*D29 -> 0
A30: Driver cum guide | B30: Day x Qty | C30: 250000 | D30: =IF((($D$2>=1)*($D$2<=3))=1,$C$2,0) -> 3 | E30: =C30*D30 -> 750000
A31: E. Others | E31: =C31*D31 -> 0
A32: E1. Miscelleneous | E32: =C32*D32 -> 0
A33: Mineral Water | B33: Karton | C33: 50000 | D33: =ROUNDUP(D2*C2*3/24,0) -> 2 | E33: =C33*D33 -> 100000
A34: Transport allowance | B34: Day x Qty | C34: 100000 | D34: 1 | E34: =C34*D34 -> 100000
A35: T Shirt | B35: Pax | C35: 60000 | D35: =D2 -> 3 | E35: =C35*D35 -> 180000
A36: E3. Bali Transfer
A37: Ferry tickets (1-way) | B37: Pax | C37: 16000 | D37: =D2 -> 3 | E37: =C37*D37 -> 48000
A38: Total Expense | E38: =SUM(E7:E37) -> 6440500
A39: Expense / Pax | E39: =E38/D2 -> 2146833.3

Sheet 4 Pax
A1: Package Name | C1: Duration (Days) | D1: No of Pax | E1: Price Per Pax
A2: 3 Day Bromo, Madakaripura Waterfall & Ijen Overland from Surabaya to Bali | C2: 3 | D2: 4 | E2: 3050000
A4: Description | B4: Unit | C4: Rate | D4: Qty | E4: Total
A5: A. Accommodation
A6: A1. Ijen
A7: Riverside Homestay - Deluxe | B7: No | C7: 337500 | D7: =ROUNDUP(D2/2,0) -> 2 | E7: =C7*D7 -> 675000
A8: A2. Bromo
A9: Joglo Kecombrang - Deluxe | B9: No | C9: 750000 | D9: =ROUNDUP(D2/2,0) -> 2 | E9: =C9*D9 -> 1500000
A10: B. Activities
A11: B1. Ijen
A12: Ijen - Ticket | B12: Pax | C12: 75000 | D12: =D2 -> 4 | E12: =C12*D12 -> 300000
A13: Medical Check up | B13: Pax | C13: 35000 | D13: =D2 -> 4 | E13: =C13*D13 -> 140000
A14: Coffee + Indo Mee | B14: Pax | C14: 25000 | D14: =D2 -> 4 | E14: =C14*D14 -> 100000
A15: Riverside - Dinner | B15: Pax | C15: 65000 | D15: =D2 -> 4 | E15: =C15*D15 -> 260000
A16: B2. Bromo
A17: Bromo - Ticket | B17: Pax | C17: 160000 | D17: =D2 -> 4 | E17: =C17*D17 -> 640000
A18: Bromo - Jeep | B18: Pax | C18: 500000 | D18: =ROUNDUP(D2/4,0) -> 1 | E18: =C18*D18 -> 500000
A19: B3. Madakaripura
A20: Motor + Ticket | B20: Pax | C20: 90000 | D20: =D2 -> 4 | E20: =C20*D20 -> 360000
A21: Madakaripura Local Guide | B21: No | C21: 100000 | D21: 1 | E21: =C21*D21 -> 100000
A22: C. Transportation
A23: C1. Vehicle
A24: Toyota Hiace | B24: Day x Qty | C24: 1100000 | D24: =IF((($D$2>=4)*($D$2<=11))=1,$C$2,0) -> 3 | E24: =C24*D24 -> 3300000
A25: C2. Parking and toll
A26: Probolingo | B26: No | C26: 200000 | D26: =IF((($D$2>=10)*($D$2<=11))=1,2,1) -> 1 | E26: =C26*D26 -> 200000
A27: D. Crews | E27: =C27*D27 -> 0
A28: D1. In house | E28: =C28*D28 -> 0
A29: Escort Guide | B29: Day x Qty | C29: 250000 | D29: =IF((($D$2>=4)*($D$2<=11))=1,$C$2,0) -> 3 | E29: =C29*D29 -> 750000
A30: E. Others | E30: =C30*D30 -> 0
A31: E1. Miscelleneous | E31: =C31*D31 -> 0
A32: Mineral Water | B32: Karton | C32: 50000 | D32: =ROUNDUP(D2*C2*3/24,0) -> 2 | E32: =C32*D32 -> 100000
A33: Transport allowance | B33: Day x Qty | C33: 100000 | D33: 1 | E33: =C33*D33 -> 100000
A34: T Shirt | B34: Pax | C34: 60000 | D34: =D2 -> 4 | E34: =C34*D34 -> 240000
A35: E3. Bali Transfer | E35: =C35*D35 -> 0
A36: Ferry tickets (1-way) | B36: Pax | C36: 16000 | D36: =D2 -> 4 | E36: =C36*D36 -> 64000
A37: Total Expense | E37: =SUM(E7:E36) -> 9329000
A38: Expense / Pax | E38: =E37/D2 -> 2332250

Sheet 5 Pax
A1: Package Name | C1: Duration (Days) | D1: No of Pax | E1: Price Per Pax
A2: 3 Day Bromo, Madakaripura Waterfall & Ijen Overland from Surabaya to Bali | C2: 3 | D2: 5 | E2: 3050000
A4: Description | B4: Unit | C4: Rate | D4: Qty | E4: Total
A5: A. Accommodation
A6: A1. Ijen
A7: Riverside Homestay - Deluxe | B7: No | C7: 337500 | D7: 1 | E7: =C7*D7 -> 337500
A8: Riverside Homestay - Family | B8: No | C8: 562500 | D8: 1 | E8: =C8*D8 -> 562500
A9: A2. Bromo
A10: Joglo Kecombrang - Deluxe | B10: No | C10: 750000 | D10: 1 | E10: =C10*D10 -> 750000
A11: Joglo Kecombrang - Family | B11: No | C11: 950000 | D11: 1 | E11: =C11*D11 -> 950000
A12: B. Activities | E12: =C12*D12 -> 0
A13: B1. Ijen | E13: =C13*D13 -> 0
A14: Ijen - Ticket | B14: Pax | C14: 75000 | D14: =D2 -> 5 | E14: =C14*D14 -> 375000
A15: Medical Check up | B15: Pax | C15: 35000 | D15: =D2 -> 5 | E15: =C15*D15 -> 175000
A16: Coffee + Indo Mee | B16: Pax | C16: 25000 | D16: =D2 -> 5 | E16: =C16*D16 -> 125000
A17: Ijen Local Guide | B17: No | C17: 250000 | D17: 1 | E17: =C17*D17 -> 250000
A18: Riverside - Dinner | B18: Pax | C18: 65000 | D18: =D2 -> 5 | E18: =C18*D18 -> 325000
A19: B2. Bromo
A20: Bromo - Ticket | B20: Pax | C20: 160000 | D20: =D2 -> 5 | E20: =C20*D20 -> 800000
A21: Bromo - Jeep | B21: Pax | C21: 500000 | D21: =ROUNDUP(D2/4,0) -> 2 | E21: =C21*D21 -> 1000000
A22: B3. Madakaripura
A23: Motor + Ticket | B23: Pax | C23: 90000 | D23: =D2 -> 5 | E23: =C23*D23 -> 450000
A24: Madakaripura Local Guide | B24: No | C24: 100000 | D24: 1 | E24: =C24*D24 -> 100000
A25: C. Transportation
A26: C1. Vehicle
A27: Toyota Hiace | B27: Day x Qty | C27: 1100000 | D27: =IF((($D$2>=4)*($D$2<=11))=1,$C$2,0) -> 3 | E27: =C27*D27 -> 3300000
A28: C2. Parking and toll
A29: Probolingo | B29: No | C29: 200000 | D29: =IF((($D$2>=10)*($D$2<=11))=1,2,1) -> 1 | E29: =C29*D29 -> 200000
A30: D. Crews
A31: D1. In house
A32: Escort Guide | B32: Day x Qty | C32: 250000 | D32: =IF((($D$2>=4)*($D$2<=11))=1,$C$2,0) -> 3 | E32: =C32*D32 -> 750000
A33: E. Others
A34: E1. Miscelleneous
A35: Mineral Water | B35: Karton | C35: 50000 | D35: =ROUNDUP(D2*C2*3/24,0) -> 2 | E35: =C35*D35 -> 100000
A36: Transport allowance | B36: Day x Qty | C36: 100000 | D36: 1 | E36: =C36*D36 -> 100000
A37: T Shirt | B37: Pax | C37: 60000 | D37: =D2 -> 5 | E37: =C37*D37 -> 300000
A38: E3. Bali Transfer
A39: Ferry tickets (1-way) | B39: Pax | C39: 16000 | D39: =D2 -> 5 | E39: =C39*D39 -> 80000
A40: Total Expense | E40: =SUM(E7:E39) -> 11030000
A41: Expense / Pax | E41: =E40/D2 -> 2206000

Sheet 6 Pax
A1: Package Name | C1: Duration (Days) | D1: No of Pax | E1: Price Per Pax
A2: 3 Day Bromo, Madakaripura Waterfall & Ijen Overland from Surabaya to Bali | C2: 3 | D2: 6 | E2: 2850000
A4: Description | B4: Unit | C4: Rate | D4: Qty | E4: Total
A5: A. Accommodation
A6: A1. Ijen
A7: Riverside Homestay - Deluxe | B7: No | C7: 337500 | D7: =ROUNDUP(D2/2,0) -> 3 | E7: =C7*D7 -> 1012500
A8: A2. Bromo
A9: Joglo Kecombrang - Deluxe | B9: No | C9: 750000 | D9: =ROUNDUP(D2/2,0) -> 3 | E9: =C9*D9 -> 2250000
A10: B. Activities
A11: B1. Ijen
A12: Ijen - Ticket | B12: Pax | C12: 75000 | D12: =D2 -> 6 | E12: =C12*D12 -> 450000
A13: Medical Check up | B13: Pax | C13: 35000 | D13: =D2 -> 6 | E13: =C13*D13 -> 210000
A14: Coffee + Indo Mee | B14: Pax | C14: 25000 | D14: =D2 -> 6 | E14: =C14*D14 -> 150000
A15: Ijen Local Guide | B15: No | C15: 250000 | D15: 1 | E15: =C15*D15 -> 250000
A16: Riverside - Dinner | B16: Pax | C16: 65000 | D16: =D2 -> 6 | E16: =C16*D16 -> 390000
A17: B2. Bromo
A18: Bromo - Ticket | B18: Pax | C18: 160000 | D18: =D2 -> 6 | E18: =C18*D18 -> 960000
A19: Bromo - Jeep | B19: Pax | C19: 500000 | D19: =ROUNDUP(D2/4,0) -> 2 | E19: =C19*D19 -> 1000000
A20: B3. Madakaripura
A21: Motor + Ticket | B21: Pax | C21: 90000 | D21: =D2 -> 6 | E21: =C21*D21 -> 540000
A22: Madakaripura Local Guide | B22: No | C22: 100000 | D22: 1 | E22: =C22*D22 -> 100000
A23: C. Transportation
A24: C1. Vehicle
A25: Toyota Hiace | B25: Day x Qty | C25: 1100000 | D25: =IF((($D$2>=4)*($D$2<=11))=1,$C$2,0) -> 3 | E25: =C25*D25 -> 3300000
A26: C2. Parking and toll
A27: Probolingo | B27: No | C27: 200000 | D27: =IF((($D$2>=10)*($D$2<=11))=1,2,1) -> 1 | E27: =C27*D27 -> 200000
A28: D. Crews
A29: D1. In house
A30: Escort Guide | B30: Day x Qty | C30: 250000 | D30: =IF((($D$2>=4)*($D$2<=11))=1,$C$2,0) -> 3 | E30: =C30*D30 -> 750000
A31: E. Others
A32: E1. Miscelleneous
A33: Mineral Water | B33: Karton | C33: 50000 | D33: =ROUNDUP(D2*C2*3/24,0) -> 3 | E33: =C33*D33 -> 150000
A34: Transport allowance | B34: Day x Qty | C34: 100000 | D34: 1 | E34: =C34*D34 -> 100000
A35: T Shirt | B35: Pax | C35: 60000 | D35: =D2 -> 6 | E35: =C35*D35 -> 360000
A36: E3. Bali Transfer
A37: Ferry tickets (1-way) | B37: Pax | C37: 16000 | D37: =D2 -> 6 | E37: =C37*D37 -> 96000
A38: Total Expense | E38: =SUM(E7:E37) -> 12268500
A39: Expense / Pax | E39: =E38/D2 -> 2044750

Sheet 7 Pax
A1: Package Name | C1: Duration (Days) | D1: No of Pax | E1: Price Per Pax
A2: 3 Day Bromo, Madakaripura Waterfall & Ijen Overland from Surabaya to Bali | C2: 3 | D2: 7 | E2: 2850000
A4: Description | B4: Unit | C4: Rate | D4: Qty | E4: Total
A5: A. Accommodation
A6: A1. Ijen
A7: Riverside Homestay - Deluxe | B7: No | C7: 337500 | D7: 2 | E7: =C7*D7 -> 675000
A8: Riverside Homestay - Family | B8: No | C8: 562500 | D8: 1 | E8: =C8*D8 -> 562500
A9: A2. Bromo
A10: Joglo Kecombrang - Deluxe | B10: No | C10: 750000 | D10: 2 | E10: =C10*D10 -> 1500000
A11: Joglo Kecombrang - Family | B11: No | C11: 950000 | D11: 1 | E11: =C11*D11 -> 950000
A12: B. Activities
A13: B1. Ijen
A14: Ijen - Ticket | B14: Pax | C14: 75000 | D14: =D2 -> 7 | E14: =C14*D14 -> 525000
A15: Medical Check up | B15: Pax | C15: 35000 | D15: =D2 -> 7 | E15: =C15*D15 -> 245000
A16: Coffee + Indo Mee | B16: Pax | C16: 25000 | D16: =D2 -> 7 | E16: =C16*D16 -> 175000
A17: Ijen Local Guide | B17: No | C17: 250000 | D17: 1 | E17: =C17*D17 -> 250000
A18: Riverside - Dinner | B18: Pax | C18: 65000 | D18: =D2 -> 7 | E18: =C18*D18 -> 455000
A19: B2. Bromo
A20: Bromo - Ticket | B20: Pax | C20: 160000 | D20: =D2 -> 7 | E20: =C20*D20 -> 1120000
A21: Bromo - Jeep | B21: Pax | C21: 500000 | D21: =ROUNDUP(D2/4,0) -> 2 | E21: =C21*D21 -> 1000000
A22: B3. Madakaripura
A23: Motor + Ticket | B23: Pax | C23: 90000 | D23: =D2 -> 7 | E23: =C23*D23 -> 630000
A24: Madakaripura Local Guide | B24: No | C24: 100000 | D24: 1 | E24: =C24*D24 -> 100000
A25: C. Transportation
A26: C1. Vehicle
A27: Toyota Hiace | B27: Day x Qty | C27: 1100000 | D27: =IF((($D$2>=4)*($D$2<=11))=1,$C$2,0) -> 3 | E27: =C27*D27 -> 3300000
A28: C2. Parking and toll
A29: Probolingo | B29: No | C29: 200000 | D29: =IF((($D$2>=10)*($D$2<=11))=1,2,1) -> 1 | E29: =C29*D29 -> 200000
A30: D. Crews
A31: D1. In house
A32: Escort Guide | B32: Day x Qty | C32: 250000 | D32: =IF((($D$2>=4)*($D$2<=11))=1,$C$2,0) -> 3 | E32: =C32*D32 -> 750000
A33: E. Others
A34: E1. Miscelleneous
A35: Mineral Water | B35: Karton | C35: 50000 | D35: =ROUNDUP(D2*C2*3/24,0) -> 3 | E35: =C35*D35 -> 150000
A36: Transport allowance | B36: Day x Qty | C36: 100000 | D36: 1 | E36: =C36*D36 -> 100000
A37: T Shirt | B37: Pax | C37: 60000 | D37: =D2 -> 7 | E37: =C37*D37 -> 420000
A38: E3. Bali Transfer
A39: Ferry tickets (1-way) | B39: Pax | C39: 16000 | D39: =D2 -> 7 | E39: =C39*D39 -> 112000
A40: Total Expense | E40: =SUM(E7:E39) -> 13219500
A41: Expense / Pax | E41: =E40/D2 -> 1888500

Sheet 8 Pax
A1: Package Name | C1: Duration (Days) | D1: No of Pax | E1: Price Per Pax
A2: 3 Day Bromo, Madakaripura Waterfall & Ijen Overland from Surabaya to Bali | C2: 3 | D2: 8 | E2: 2550000
A4: Description | B4: Unit | C4: Rate | D4: Qty | E4: Total
A5: A. Accommodation
A6: A1. Ijen
A7: Riverside Homestay - Deluxe | B7: No | C7: 337500 | D7: =ROUNDUP(D2/2,0) -> 4 | E7: =C7*D7 -> 1350000
A8: A2. Bromo
A9: Joglo Kecombrang - Deluxe | B9: No | C9: 750000 | D9: =ROUNDUP(D2/2,0) -> 4 | E9: =C9*D9 -> 3000000
A10: B. Activities
A11: B1. Ijen
A12: Ijen - Ticket | B12: Pax | C12: 75000 | D12: =D2 -> 8 | E12: =C12*D12 -> 600000
A13: Medical Check up | B13: Pax | C13: 35000 | D13: =D2 -> 8 | E13: =C13*D13 -> 280000
A14: Coffee + Indo Mee | B14: Pax | C14: 25000 | D14: =D2 -> 8 | E14: =C14*D14 -> 200000
A15: Ijen Local Guide | B15: No | C15: 250000 | D15: 1 | E15: =C15*D15 -> 250000
A16: Riverside - Dinner | B16: Pax | C16: 65000 | D16: =D2 -> 8 | E16: =C16*D16 -> 520000
A17: B2. Bromo
A18: Bromo - Ticket | B18: Pax | C18: 160000 | D18: =D2 -> 8 | E18: =C18*D18 -> 1280000
A19: Bromo - Jeep | B19: Pax | C19: 500000 | D19: =ROUNDUP(D2/4,0) -> 2 | E19: =C19*D19 -> 1000000
A20: B3. Madakaripura
A21: Motor + Ticket | B21: Pax | C21: 90000 | D21: =D2 -> 8 | E21: =C21*D21 -> 720000
A22: Madakaripura Local Guide | B22: No | C22: 100000 | D22: 1 | E22: =C22*D22 -> 100000
A23: C. Transportation
A24: C1. Vehicle
A25: Toyota Hiace | B25: Day x Qty | C25: 1100000 | D25: =IF((($D$2>=4)*($D$2<=11))=1,$C$2,0) -> 3 | E25: =C25*D25 -> 3300000
A26: C2. Parking and toll
A27: Probolingo | B27: No | C27: 200000 | D27: =IF((($D$2>=10)*($D$2<=11))=1,2,1) -> 1 | E27: =C27*D27 -> 200000
A28: D. Crews
A29: D1. In house
A30: Escort Guide | B30: Day x Qty | C30: 250000 | D30: =IF((($D$2>=4)*($D$2<=11))=1,$C$2,0) -> 3 | E30: =C30*D30 -> 750000
A31: E. Others
A32: E1. Miscelleneous
A33: Mineral Water | B33: Karton | C33: 50000 | D33: =ROUNDUP(D2*C2*3/24,0) -> 3 | E33: =C33*D33 -> 150000
A34: Transport allowance | B34: Day x Qty | C34: 100000 | D34: 1 | E34: =C34*D34 -> 100000
A35: T Shirt | B35: Pax | C35: 60000 | D35: =D2 -> 8 | E35: =C35*D35 -> 480000
A36: E3. Bali Transfer
A37: Ferry tickets (1-way) | B37: Pax | C37: 16000 | D37: =D2 -> 8 | E37: =C37*D37 -> 128000
A38: Total Expense | E38: =SUM(E7:E37) -> 14408000
A39: Expense / Pax | E39: =E38/D2 -> 1801000

Sheet 9 Pax
A1: Package Name | C1: Duration (Days) | D1: No of Pax | E1: Price Per Pax
A2: 3 Day Bromo, Madakaripura Waterfall & Ijen Overland from Surabaya to Bali | C2: 3 | D2: 9 | E2: 2550000
A4: Description | B4: Unit | C4: Rate | D4: Qty | E4: Total
A5: A. Accommodation
A6: A1. Ijen
A7: Riverside Homestay - Deluxe | B7: No | C7: 337500 | D7: 3 | E7: =C7*D7 -> 1012500
A8: Riverside Homestay - Family | B8: No | C8: 562500 | D8: 1 | E8: =C8*D8 -> 562500
A9: A2. Bromo
A10: Joglo Kecombrang - Deluxe | B10: No | C10: 750000 | D10: 3 | E10: =C10*D10 -> 2250000
A11: Joglo Kecombrang - Family | B11: No | C11: 950000 | D11: 1 | E11: =C11*D11 -> 950000
A12: B. Activities
A13: B1. Ijen
A14: Ijen - Ticket | B14: Pax | C14: 75000 | D14: =D2 -> 9 | E14: =C14*D14 -> 675000
A15: Medical Check up | B15: Pax | C15: 35000 | D15: =D2 -> 9 | E15: =C15*D15 -> 315000
A16: Coffee + Indo Mee | B16: Pax | C16: 25000 | D16: =D2 -> 9 | E16: =C16*D16 -> 225000
A17: Ijen Local Guide | B17: No | C17: 250000 | D17: 1 | E17: =C17*D17 -> 250000
A18: Riverside - Dinner | B18: Pax | C18: 65000 | D18: =D2 -> 9 | E18: =C18*D18 -> 585000
A19: B2. Bromo
A20: Bromo - Ticket | B20: Pax | C20: 160000 | D20: =D2 -> 9 | E20: =C20*D20 -> 1440000
A21: Bromo - Jeep | B21: Pax | C21: 500000 | D21: =ROUNDUP(D2/4,0) -> 3 | E21: =C21*D21 -> 1500000
A22: B3. Madakaripura
A23: Motor + Ticket | B23: Pax | C23: 90000 | D23: =D2 -> 9 | E23: =C23*D23 -> 810000
A24: Madakaripura Local Guide | B24: No | C24: 100000 | D24: 1 | E24: =C24*D24 -> 100000
A25: C. Transportation
A26: C1. Vehicle
A27: Toyota Hiace | B27: Day x Qty | C27: 1100000 | D27: =IF((($D$2>=4)*($D$2<=11))=1,$C$2,0) -> 3 | E27: =C27*D27 -> 3300000
A28: C2. Parking and toll
A29: Probolingo | B29: No | C29: 200000 | D29: =IF((($D$2>=10)*($D$2<=11))=1,2,1) -> 1 | E29: =C29*D29 -> 200000
A30: D. Crews
A31: D1. In house
A32: Escort Guide | B32: Day x Qty | C32: 250000 | D32: =IF((($D$2>=4)*($D$2<=11))=1,$C$2,0) -> 3 | E32: =C32*D32 -> 750000
A33: E. Others
A34: E1. Miscelleneous
A35: Mineral Water | B35: Karton | C35: 50000 | D35: =ROUNDUP(D2*C2*3/24,0) -> 4 | E35: =C35*D35 -> 200000
A36: Transport allowance | B36: Day x Qty | C36: 100000 | D36: 1 | E36: =C36*D36 -> 100000
A37: T Shirt | B37: Pax | C37: 60000 | D37: =D2 -> 9 | E37: =C37*D37 -> 540000
A38: E3. Bali Transfer
A39: Ferry tickets (1-way) | B39: Pax | C39: 16000 | D39: =D2 -> 9 | E39: =C39*D39 -> 144000
A40: Total Expense | E40: =SUM(E7:E39) -> 15909000
A41: Expense / Pax | E41: =E40/D2 -> 1767666.7

Sheet 10 Pax
A1: Package Name | C1: Duration (Days) | D1: No of Pax | E1: Price Per Pax
A2: 3 Day Bromo, Madakaripura Waterfall & Ijen Overland from Surabaya to Bali | C2: 3 | D2: 10 | E2: 2550000
A4: Description | B4: Unit | C4: Rate | D4: Qty | E4: Total
A5: A. Accommodation
A6: A1. Ijen
A7: Riverside Homestay - Deluxe | B7: No | C7: 337500 | D7: =ROUNDUP(D2/2,0) -> 5 | E7: =C7*D7 -> 1687500
A8: A2. Bromo
A9: Joglo Kecombrang - Deluxe | B9: No | C9: 750000 | D9: =ROUNDUP(D2/2,0) -> 5 | E9: =C9*D9 -> 3750000
A10: B. Activities
A11: B1. Ijen
A12: Ijen - Ticket | B12: Pax | C12: 75000 | D12: =D2 -> 10 | E12: =C12*D12 -> 750000
A13: Medical Check up | B13: Pax | C13: 35000 | D13: =D2 -> 10 | E13: =C13*D13 -> 350000
A14: Coffee + Indo Mee | B14: Pax | C14: 25000 | D14: =D2 -> 10 | E14: =C14*D14 -> 250000
A15: Ijen Local Guide | B15: No | C15: 250000 | D15: 1 | E15: =C15*D15 -> 250000
A16: Riverside - Dinner | B16: Pax | C16: 65000 | D16: =D2 -> 10 | E16: =C16*D16 -> 650000
A17: B2. Bromo
A18: Bromo - Ticket | B18: Pax | C18: 160000 | D18: =D2 -> 10 | E18: =C18*D18 -> 1600000
A19: Bromo - Jeep | B19: Pax | C19: 500000 | D19: =ROUNDUP(D2/4,0) -> 3 | E19: =C19*D19 -> 1500000
A20: B3. Madakaripura
A21: Motor + Ticket | B21: Pax | C21: 90000 | D21: =D2 -> 10 | E21: =C21*D21 -> 900000
A22: Madakaripura Local Guide | B22: No | C22: 100000 | D22: 1 | E22: =C22*D22 -> 100000
A23: C. Transportation
A24: C1. Vehicle
A25: Toyota Hiace | B25: Day x Qty | C25: 1100000 | D25: =IF((($D$2>=4)*($D$2<=11))=1,$C$2,0) -> 3 | E25: =C25*D25 -> 3300000
A26: Extra Luggage | B26: Day x Qty | C26: =250000+200000+200000 -> 650000 | D26: 3 | E26: =C26*D26 -> 1950000
A27: C2. Parking and toll
A28: Probolingo | B28: No | C28: 200000 | D28: =IF((($D$2>=10)*($D$2<=11))=1,2,1) -> 2 | E28: =C28*D28 -> 400000
A29: D. Crews
A30: D1. In house
A31: Escort Guide | B31: Day x Qty | C31: 250000 | D31: =IF((($D$2>=4)*($D$2<=11))=1,$C$2,0) -> 3 | E31: =C31*D31 -> 750000
A32: E. Others
A33: E1. Miscelleneous
A34: Mineral Water | B34: Karton | C34: 50000 | D34: =ROUNDUP(D2*C2*3/24,0) -> 4 | E34: =C34*D34 -> 200000
A35: Transport allowance | B35: Day x Qty | C35: 100000 | D35: 1 | E35: =C35*D35 -> 100000
A36: T Shirt | B36: Pax | C36: 60000 | D36: =D2 -> 10 | E36: =C36*D36 -> 600000
A37: E3. Bali Transfer
A38: Ferry tickets (1-way) | B38: Pax | C38: 16000 | D38: =D2 -> 10 | E38: =C38*D38 -> 160000
A39: Total Expense | E39: =SUM(E7:E38) -> 19247500
A40: Expense / Pax | E40: =E39/D2 -> 1924750

Sheet 11 Pax
A1: Package Name | C1: Duration (Days) | D1: No of Pax | E1: Price Per Pax
A2: 3 Day Bromo, Madakaripura Waterfall & Ijen Overland from Surabaya to Bali | C2: 3 | D2: 11 | E2: 2450000
A4: Description | B4: Unit | C4: Rate | D4: Qty | E4: Total
A5: A. Accommodation
A6: A1. Ijen
A7: Riverside Homestay - Deluxe | B7: No | C7: 337500 | D7: 4 | E7: =C7*D7 -> 1350000
A8: Riverside Homestay - Family | B8: No | C8: 562500 | D8: 1 | E8: =C8*D8 -> 562500
A9: A2. Bromo
A10: Joglo Kecombrang - Deluxe | B10: No | C10: 750000 | D10: 4 | E10: =C10*D10 -> 3000000
A11: Joglo Kecombrang - Family | B11: No | C11: 950000 | D11: 1 | E11: =C11*D11 -> 950000
A12: B. Activities
A13: B1. Ijen
A14: Ijen - Ticket | B14: Pax | C14: 75000 | D14: =D2 -> 11 | E14: =C14*D14 -> 825000
A15: Medical Check up | B15: Pax | C15: 35000 | D15: =D2 -> 11 | E15: =C15*D15 -> 385000
A16: Coffee + Indo Mee | B16: Pax | C16: 25000 | D16: =D2 -> 11 | E16: =C16*D16 -> 275000
A17: Ijen Local Guide | B17: No | C17: 250000 | D17: 1 | E17: =C17*D17 -> 250000
A18: Riverside - Dinner | B18: Pax | C18: 65000 | D18: =D2 -> 11 | E18: =C18*D18 -> 715000
A19: B2. Bromo
A20: Bromo - Ticket | B20: Pax | C20: 160000 | D20: =D2 -> 11 | E20: =C20*D20 -> 1760000
A21: Bromo - Jeep | B21: Pax | C21: 500000 | D21: =ROUNDUP(D2/4,0) -> 3 | E21: =C21*D21 -> 1500000
A22: B3. Madakaripura
A23: Motor + Ticket | B23: Pax | C23: 90000 | D23: =D2 -> 11 | E23: =C23*D23 -> 990000
A24: Madakaripura Local Guide | B24: No | C24: 100000 | D24: 1 | E24: =C24*D24 -> 100000
A25: C. Transportation
A26: C1. Vehicle
A27: Toyota Hiace | B27: Day x Qty | C27: 1100000 | D27: =IF((($D$2>=4)*($D$2<=11))=1,$C$2,0) -> 3 | E27: =C27*D27 -> 3300000
A28: Extra Luggage | B28: Day x Qty | C28: =250000+200000+200000 -> 650000 | D28: 3 | E28: =C28*D28 -> 1950000
A29: C2. Parking and toll
A30: Probolingo | B30: No | C30: 200000 | D30: =IF((($D$2>=10)*($D$2<=11))=1,2,1) -> 2 | E30: =C30*D30 -> 400000
A31: D. Crews
A32: D1. In house
A33: Escort Guide | B33: Day x Qty | C33: 250000 | D33: =IF((($D$2>=4)*($D$2<=11))=1,$C$2,0) -> 3 | E33: =C33*D33 -> 750000
A34: E. Others
A35: E1. Miscelleneous
A36: Mineral Water | B36: Karton | C36: 50000 | D36: =ROUNDUP(D2*C2*3/24,0) -> 5 | E36: =C36*D36 -> 250000
A37: Transport allowance | B37: Day x Qty | C37: 100000 | D37: 1 | E37: =C37*D37 -> 100000
A38: T Shirt | B38: Pax | C38: 60000 | D38: =D2 -> 11 | E38: =C38*D38 -> 660000
A39: E3. Bali Transfer
A40: Ferry tickets (1-way) | B40: Pax | C40: 16000 | D40: =D2 -> 11 | E40: =C40*D40 -> 176000
A41: Total Expense | E41: =SUM(E7:E40) -> 20248500
...
