Workbook

Sheet Calculation
A1: Package Name | B1: ID | C1: Duration (Days) | D1: No of Pax
A2: Ultimate East Java Experience: 5D4N Ijen Crater, Tumpak Sewu & Bromo | B2: 56 | C2: 5 | D2: 8
A4: Description | B4: Unit | C4: Rate | D4: Qty | E4: Total
A5: A. Accommodation
A6: A1. Ijen
A7: Luminor Banyuwangi | B7: No | C7: 500000
A8: Santika Banyuwangi | B8: No | C8: 560000
A9: Grand Padis - Double/Twin | B9: No | C9: 435000 | D9: =ROUNDUP($D$2/2,0) -> 4 | E9: =C9*D9 -> 1740000
A10: Grand Padis - Extra Bed | B10: No | C10: 300000 | E10: =C10*D10 -> 0
A11: Baratha - Superior | B11: No | C11: 250000 | E11: =C11*D11 -> 0
A12: Baratha - Deluxe | B12: No | C12: 275000 | E12: =C12*D12 -> 0
A13: Baratha - Family | B13: No | C13: 450000 | E13: =C13*D13 -> 0
A14: Baratha - Apartement | B14: No | C14: 450000 | E14: =C14*D14 -> 0
A15: Riverside Homestay - Deluxe | B15: No | C15: 337500 | E15: =C15*D15 -> 0
A16: Riverside Homestay - Executive | B16: No | C16: 375000 | E16: =C16*D16 -> 0
A17: Riverside Homestay - Emerald | B17: No | C17: 412500 | E17: =C17*D17 -> 0
A18: Riverside Homestay - Platinum | B18: No | C18: 487500 | E18: =C18*D18 -> 0
A19: Riverside Homestay - Family | B19: No | C19: 562500 | E19: =C19*D19 -> 0
A20: A2. Bromo
A21: Joglo Kecombrang - Deluxe | B21: No | C21: 750000 | D21: =ROUNDUP($D$2/2,0) -> 4 | E21: =C21*D21 -> 3000000
A22: Joglo Kecombrang - Family | B22: No | C22: 950000 | E22: =C22*D22 -> 0
A23: Joglo Kecombrang - Extra Bed | B23: No | C23: 300000 | E23: =C23*D23 -> 0
A24: Bromo Terrace - Deluxe Twin | B24: No | C24: 1250000 | E24: =C24*D24 -> 0
A25: Bromo Terrace - Deluxe Double | B25: No | C25: 1200000 | E25: =C25*D25 -> 0
A26: Bromo Terrace - Deluxe Double Hillview | B26: No | C26: 1350000 | E26: =C26*D26 -> 0
A27: Bromo Terrace - Extra bed | B27: No | C27: 300000 | E27: =C27*D27 -> 0
A28: Manis Ae Bromo - Single Cabin | B28: No | C28: 1220000 | E28: =C28*D28 -> 0
A29: Manis Ae Bromo - Family Cabin | B29: No | C29: 1620000 | E29: =C29*D29 -> 0
A30: Whiz Bromo - Superior | B30: No | C30: 550000 | E30: =C30*D30 -> 0
A31: A3. Lumajang / Malang / Jember
A32: Atria Malang - Deluxe | B32: No | C32: 610000 | E32: =C32*D32 -> 0
A33: Atria Malang - Extra bed | B33: No | C33: 350000 | E33: =C33*D33 -> 0
A34: 101 Malang (Without Breakfast) | B34: No | C34: 600000 | E34: =C34*D34 -> 0
A35: Artha Cottage - Deluxe | B35: No | C35: 425000
A36: Doho Homestay - Deluxe | B36: No | C36: 260000 | D36: =ROUNDUP($D$2/2,0) -> 4 | E36: =C36*D36 -> 1040000
A37: Doho Homestay - Executive | B37: No | C37: 300000 | E37: =C37*D37 -> 0
A38: Doho Homestay - Emerald | B38: No | C38: 316000 | E38: =C38*D38 -> 0
A39: Doho Homestay - Platinum | B39: No | C39: 380000 | E39: =C39*D39 -> 0
A40: Doho Homestay - Family | B40: No | C40: 440000 | E40: =C40*D40 -> 0
A41: Yanto - Cottage incl. dinner | B41: No | C41: 450000 | E41: =C41*D41 -> 0
...

Sheet Summary
A1: Pax | B1: Expense / Pax | C1: Total Expense | D1: Harga / Pax | E1: Total Harga | F1: Margin | G1: Presentase Margin | I1: Naikkan harga
A2: 2 | B2: ='2 Pax Safari'!E46 -> 3315000 | C2: =B2*A2 -> 6630000 | D2: 4300000 | E2: =D2*A2 -> 8600000 | F2: =E2-C2 -> 1970000 | G2: =F2/E2*100 -> 22.906977 | I2: 4300000
A3: 3 | B3: ='3 Pax Safari'!E47 -> 2613333.3 | C3: =B3*A3 -> 7840000 | D3: 4100000 | E3: =D3*A3 -> 12300000 | F3: =E3-C3 -> 4460000 | G3: =F3/E3*100 -> 36.260163 | I3: 4100000
A4: 4 | B4: ='4 Pax Safari'!E47 -> 3050000 | C4: =B4*A4 -> 12200000 | D4: 3900000 | E4: =D4*A4 -> 15600000 | F4: =E4-C4 -> 3400000 | G4: =F4/E4*100 -> 21.794872 | I4: 3900000
A5: 5 | B5: ='5 Pax Safari'!E47 -> 2782000 | C5: =B5*A5 -> 13910000 | D5: 3900000 | E5: =D5*A5 -> 19500000 | F5: =E5-C5 -> 5590000 | G5: =F5/E5*100 -> 28.666667 | I5: 3900000
A6: 6 | B6: ='6 Pax Safari'!E47 -> 2686666.7 | C6: =B6*A6 -> 16120000 | D6: 3700000 | E6: =D6*A6 -> 22200000 | F6: =E6-C6 -> 6080000 | G6: =F6/E6*100 -> 27.387387 | I6: 3700000
A7: 7 | B7: ='7 Pax Safari'!E47 -> 2475714.3 | C7: =B7*A7 -> 17330000 | D7: 3700000 | E7: =D7*A7 -> 25900000 | F7: =E7-C7 -> 8570000 | G7: =F7/E7*100 -> 33.088803 | I7: 3700000
A8: 8 | B8: ='8 Pax Safari'!E47 -> 2442500 | C8: =B8*A8 -> 19540000 | D8: 3500000 | E8: =D8*A8 -> 28000000 | F8: =E8-C8 -> 8460000 | G8: =F8/E8*100 -> 30.214286 | I8: 3500000
A9: 9 | B9: ='9 Pax Safari'!E47 -> 2361111.1 | C9: =B9*A9 -> 21250000 | D9: 3500000 | E9: =D9*A9 -> 31500000 | F9: =E9-C9 -> 10250000 | G9: =F9/E9*100 -> 32.539683 | I9: 3500000
A10: 10 | B10: ='10 Pax Safari'!E47 -> 2582000 | C10: =B10*A10 -> 25820000 | D10: 3500000 | E10: =D10*A10 -> 35000000 | F10: =E10-C10 -> 9180000 | G10: =F10/E10*100 -> 26.228571 | I10: 3500000
A11: 11 | B11: ='11 Pax Safari'!E47 -> 2457272.7 | C11: =B11*A11 -> 27030000 | D11: 3400000 | E11: =D11*A11 -> 37400000 | F11: =E11-C11 -> 10370000 | G11: =F11/E11*100 -> 27.727273 | I11: 3400000
A12: 12 | B12: ='12 Pax Safari'!E47 -> 2636666.7 | C12: =B12*A12 -> 31640000 | D12: 3400000 | E12: =D12*A12 -> 40800000 | F12: =E12-C12 -> 9160000 | G12: =F12/E12*100 -> 22.45098 | I12: 3400000

Sheet 8 Pax Ori
A1: Package Name | B1: ID | C1: Duration (Days) | D1: No of Pax
A2: Ultimate East Java Experience: 5D4N Ijen Crater, Tumpak Sewu & Bromo | B2: 56 | C2: 5 | D2: 8
A4: Description | B4: Unit | C4: Rate | D4: Qty | E4: Total
A5: A. Accommodation
A6: A1. Ijen
A7: Luminor Banyuwangi | B7: No | C7: 500000
A8: Santika Banyuwangi | B8: No | C8: 560000
A9: Grand Padis - Double/Twin | B9: No | C9: 435000 | D9: =ROUNDUP($D$2/2,0) -> 4 | E9: =C9*D9 -> 1740000
A10: Grand Padis - Extra Bed | B10: No | C10: 300000 | E10: =C10*D10 -> 0
A11: Baratha - Superior | B11: No | C11: 250000 | E11: =C11*D11 -> 0
A12: Baratha - Deluxe | B12: No | C12: 275000 | E12: =C12*D12 -> 0
A13: Baratha - Family | B13: No | C13: 450000 | E13: =C13*D13 -> 0
A14: Baratha - Apartement | B14: No | C14: 450000 | E14: =C14*D14 -> 0
A15: Riverside Homestay - Deluxe | B15: No | C15: 337500 | E15: =C15*D15 -> 0
A16: Riverside Homestay - Executive | B16: No | C16: 375000 | E16: =C16*D16 -> 0
A17: Riverside Homestay - Emerald | B17: No | C17: 412500 | E17: =C17*D17 -> 0
A18: Riverside Homestay - Platinum | B18: No | C18: 487500 | E18: =C18*D18 -> 0
A19: Riverside Homestay - Family | B19: No | C19: 562500 | E19: =C19*D19 -> 0
A20: A2. Bromo
A21: Joglo Kecombrang - Deluxe | B21: No | C21: 750000 | D21: =ROUNDUP($D$2/2,0) -> 4 | E21: =C21*D21 -> 3000000
A22: Joglo Kecombrang - Family | B22: No | C22: 950000 | E22: =C22*D22 -> 0
A23: Joglo Kecombrang - Extra Bed | B23: No | C23: 300000 | E23: =C23*D23 -> 0
A24: Bromo Terrace - Deluxe Twin | B24: No | C24: 1250000 | E24: =C24*D24 -> 0
A25: Bromo Terrace - Deluxe Double | B25: No | C25: 1200000 | E25: =C25*D25 -> 0
A26: Bromo Terrace - Deluxe Double Hillview | B26: No | C26: 1350000 | E26: =C26*D26 -> 0
A27: Bromo Terrace - Extra bed | B27: No | C27: 300000 | E27: =C27*D27 -> 0
A28: Manis Ae Bromo - Single Cabin | B28: No | C28: 1220000 | E28: =C28*D28 -> 0
A29: Manis Ae Bromo - Family Cabin | B29: No | C29: 1620000 | E29: =C29*D29 -> 0
A30: Whiz Bromo - Superior | B30: No | C30: 550000 | E30: =C30*D30 -> 0
A31: A3. Lumajang / Malang / Jember
A32: Atria Malang - Deluxe | B32: No | C32: 610000 | E32: =C32*D32 -> 0
A33: Atria Malang - Extra bed | B33: No | C33: 350000 | E33: =C33*D33 -> 0
A34: 101 Malang (Without Breakfast) | B34: No | C34: 600000 | E34: =C34*D34 -> 0
A35: Artha Cottage - Deluxe | B35: No | C35: 425000
A36: Doho Homestay - Deluxe | B36: No | C36: 260000 | D36: =ROUNDUP($D$2/2,0) -> 4 | E36: =C36*D36 -> 1040000
A37: Doho Homestay - Executive | B37: No | C37: 300000 | E37: =C37*D37 -> 0
A38: Doho Homestay - Emerald | B38: No | C38: 316000 | E38: =C38*D38 -> 0
A39: Doho Homestay - Platinum | B39: No | C39: 380000 | E39: =C39*D39 -> 0
A40: Doho Homestay - Family | B40: No | C40: 440000 | E40: =C40*D40 -> 0
A41: Yanto - Cottage incl. dinner | B41: No | C41: 450000 | E41: =C41*D41 -> 0
...

Sheet 12 Pax Ori
A1: Package Name | B1: ID | C1: Duration (Days) | D1: No of Pax
A2: Ultimate East Java Experience: 5D4N Ijen Crater, Tumpak Sewu & Bromo | B2: 56 | C2: 5 | D2: 12
A4: Description | B4: Unit | C4: Rate | D4: Qty | E4: Total
A5: A. Accommodation
A6: A1. Ijen
A7: Luminor Banyuwangi | B7: No | C7: 500000
A8: Santika Banyuwangi | B8: No | C8: 560000
A9: Grand Padis - Double/Twin | B9: No | C9: 435000 | D9: =ROUNDUP($D$2/2,0) -> 6 | E9: =C9*D9 -> 2610000
A10: Grand Padis - Extra Bed | B10: No | C10: 300000 | E10: =C10*D10 -> 0
A11: Baratha - Superior | B11: No | C11: 250000 | E11: =C11*D11 -> 0
A12: Baratha - Deluxe | B12: No | C12: 275000 | E12: =C12*D12 -> 0
A13: Baratha - Family | B13: No | C13: 450000 | E13: =C13*D13 -> 0
A14: Baratha - Apartement | B14: No | C14: 450000 | E14: =C14*D14 -> 0
A15: Riverside Homestay - Deluxe | B15: No | C15: 337500 | E15: =C15*D15 -> 0
A16: Riverside Homestay - Executive | B16: No | C16: 375000 | E16: =C16*D16 -> 0
A17: Riverside Homestay - Emerald | B17: No | C17: 412500 | E17: =C17*D17 -> 0
A18: Riverside Homestay - Platinum | B18: No | C18: 487500 | E18: =C18*D18 -> 0
A19: Riverside Homestay - Family | B19: No | C19: 562500 | E19: =C19*D19 -> 0
A20: A2. Bromo
A21: Joglo Kecombrang - Deluxe | B21: No | C21: 750000 | D21: =ROUNDUP($D$2/2,0) -> 6 | E21: =C21*D21 -> 4500000
A22: Joglo Kecombrang - Family | B22: No | C22: 950000 | E22: =C22*D22 -> 0
A23: Joglo Kecombrang - Extra Bed | B23: No | C23: 300000 | E23: =C23*D23 -> 0
A24: Bromo Terrace - Deluxe Twin | B24: No | C24: 1250000 | E24: =C24*D24 -> 0
A25: Bromo Terrace - Deluxe Double | B25: No | C25: 1200000 | E25: =C25*D25 -> 0
A26: Bromo Terrace - Deluxe Double Hillview | B26: No | C26: 1350000 | E26: =C26*D26 -> 0
A27: Bromo Terrace - Extra bed | B27: No | C27: 300000 | E27: =C27*D27 -> 0
A28: Manis Ae Bromo - Single Cabin | B28: No | C28: 1220000 | E28: =C28*D28 -> 0
A29: Manis Ae Bromo - Family Cabin | B29: No | C29: 1620000 | E29: =C29*D29 -> 0
A30: Whiz Bromo - Superior | B30: No | C30: 550000 | E30: =C30*D30 -> 0
A31: A3. Lumajang / Malang / Jember
A32: Atria Malang - Deluxe | B32: No | C32: 610000 | E32: =C32*D32 -> 0
A33: Atria Malang - Extra bed | B33: No | C33: 350000 | E33: =C33*D33 -> 0
A34: 101 Malang (Without Breakfast) | B34: No | C34: 600000 | E34: =C34*D34 -> 0
A35: Artha Cottage - Deluxe | B35: No | C35: 425000
A36: Doho Homestay - Deluxe | B36: No | C36: 260000 | D36: =ROUNDUP($D$2/2,0) -> 6 | E36: =C36*D36 -> 1560000
A37: Doho Homestay - Executive | B37: No | C37: 300000 | E37: =C37*D37 -> 0
A38: Doho Homestay - Emerald | B38: No | C38: 316000 | E38: =C38*D38 -> 0
A39: Doho Homestay - Platinum | B39: No | C39: 380000 | E39: =C39*D39 -> 0
A40: Doho Homestay - Family | B40: No | C40: 440000 | E40: =C40*D40 -> 0
A41: Yanto - Cottage incl. dinner | B41: No | C41: 450000 | E41: =C41*D41 -> 0
...

Sheet 2 Pax Safari
A1: Package Name | C1: Duration (Days) | D1: No of Pax
A2: 3D 2N Safari Park - Bromo - Surabaya | C2: 3 | D2: 2
A4: Description | B4: Unit | C4: Rate | D4: Qty | E4: Total
A5: A2. Bromo
A6: Joglo Kecombrang - Deluxe | B6: No | C6: 750000 | D6: =ROUNDUP($D$2/2,0) -> 1 | E6: =C6*D6 -> 750000
A7: Joglo Kecombrang - Family | B7: No | C7: 950000 | E7: =C7*D7 -> 0
A8: Joglo Kecombrang - Extra Bed | B8: No | C8: 300000 | E8: =C8*D8 -> 0
A9: A3. Taman Safari Prigen
A10: Baobab Safari Resort - Deluxe Safari View (Weekend) | B10: No | C10: 1700000 | D10: =ROUNDUP($D$2/2,0) -> 1 | E10: =C10*D10 -> 1700000
A11: B. Activities
A12: B2. Bromo
A13: Bromo - Ticket | B13: Pax | C13: 160000 | D13: =D2 -> 2 | E13: =C13*D13 -> 320000
A14: Bromo - Jeep | B14: Pax | C14: 500000 | D14: =ROUNDUP(D2/4,0) -> 1 | E14: =C14*D14 -> 500000
A15: B3. Madakaripura
A16: Motor + Ticket | B16: Pax | C16: 90000 | D16: =D2 -> 2 | E16: =C16*D16 -> 180000
A17: Madakaripura Local Guide | B17: No | C17: 100000 | D17: 1 | E17: =C17*D17 -> 100000
A18: B4. Taman Safari
A19: Breakfast With Giraffe (Max 4 pax / sesi) - Add on | B19: Pax | C19: 650000 | E19: =C19*D19 -> 0
A20: Surcharge Taman Safari Ticket | B20: No | C20: 150000 | D20: =$D$2 -> 2 | E20: =C20*D20 -> 300000
A21: Ticket Driver & Guide | B21: Pax | C21: 200000 | D21: 1 | E21: =C21*D21 -> 200000
A22: Parking | B22: No | C22: 10000 | D22: 1 | E22: =C22*D22 -> 10000
A23: C. Transportation
A24: C1. Vehicle
A25: Avanza | B25: Day x Qty | C25: 450000 | D25: =IF($D$2=1,3, IF($D$2=2,3,0)) -> 3 | E25: =C25*D25 -> 1350000
A26: Innova | B26: Day x Qty | C26: 550000 | D26: =IF($D$2=3,4, 0) -> 0 | E26: =C26*D26 -> 0
A27: Toyota Hiace | B27: Day x Qty | C27: 1100000 | D27: =IF((($D$2>=4)*($D$2<=11))=1,4,0) -> 0 | E27: =C27*D27 -> 0
A28: Toyota Hiace Premio (4-6pax) | B28: Day x Qty | C28: 1300000 | E28: =C28*D28 -> 0
A29: Extra Luggage | B29: Day x Qty | C29: 2720000 | D29: =IF((($D$2>=10)*($D$2<=11))=1,1,0) -> 0 | E29: =C29*D29 -> 0
A30: C2. Parking and toll
A31: Probolingo | B31: No | C31: 200000 | D31: =IF((($D$2>=10)*($D$2<=11))=1,2,1) -> 1 | E31: =C31*D31 -> 200000
A32: Probolinggo + Malang | B32: No | C32: 300000 | E32: =C32*D32 -> 0
A33: D. Crews
A34: D1. In house
A35: Driver cum guide | B35: Day x Qty | C35: 250000 | D35: =IF((($D$2>=1)*($D$2<=3))=1,3,0) -> 3 | E35: =C35*D35 -> 750000
A36: Escort Guide | B36: Day x Qty | C36: 250000 | D36: =IF((($D$2>=4)*($D$2<=11))=1,3,0) -> 0 | E36: =C36*D36 -> 0
A37: Driver Only | B37: Day x Qty | C37: 200000 | E37: =C37*D37 -> 0
A38: E. Others
A39: E1. Miscelleneous
A40: Mineral Water | B40: Karton | C40: 50000 | D40: =ROUNDUP(D2*4*3/24,0) -> 1 | E40: =C40*D40 -> 50000
A41: Transport allowance | B41: Day x Qty | C41: 100000 | D41: 1 | E41: =C41*D41 -> 100000
...

Sheet 3 Pax Safari
A1: Package Name | C1: Duration (Days) | D1: No of Pax
A2: 3D 2N Safari Park - Bromo - Surabaya | C2: 3 | D2: 3
A4: Description | B4: Unit | C4: Rate | D4: Qty | E4: Total
A5: A2. Bromo
A6: Joglo Kecombrang - Deluxe | B6: No | C6: 750000 | E6: =C6*D6 -> 0
A7: Joglo Kecombrang - Family | B7: No | C7: 950000 | D7: 1 | E7: =C7*D7 -> 950000
A8: Joglo Kecombrang - Extra Bed | B8: No | C8: 300000 | E8: =C8*D8 -> 0
A9: A3. Taman Safari Prigen
A10: Baobab Safari Resort - Deluxe Safari View (Weekend) | B10: No | C10: 1700000 | D10: 1 | E10: =C10*D10 -> 1700000
A11: Baobab Safari Resort - Extra Bed | B11: No | C11: 500000 | D11: 1 | E11: =C11*D11 -> 500000
A12: B. Activities
A13: B2. Bromo
A14: Bromo - Ticket | B14: Pax | C14: 160000 | D14: =$D$2 -> 3 | E14: =C14*D14 -> 480000
A15: Bromo - Jeep | B15: Pax | C15: 500000 | D15: =ROUNDUP(D2/4,0) -> 1 | E15: =C15*D15 -> 500000
A16: B3. Madakaripura
A17: Motor + Ticket | B17: Pax | C17: 90000 | D17: =$D$2 -> 3 | E17: =C17*D17 -> 270000
A18: Madakaripura Local Guide | B18: No | C18: 100000 | D18: 1 | E18: =C18*D18 -> 100000
A19: B4. Taman Safari
A20: Breakfast With Giraffe (Max 4 pax / sesi) - Add on | B20: Pax | C20: 650000 | E20: =C20*D20 -> 0
A21: Surcharge Taman Safari Ticket | B21: No | C21: 150000 | D21: =$D$2 -> 3 | E21: =C21*D21 -> 450000
A22: Ticket Driver & Guide | B22: Pax | C22: 200000 | D22: 1 | E22: =C22*D22 -> 200000
A23: Parking | B23: No | C23: 10000 | D23: 1 | E23: =C23*D23 -> 10000
A24: C. Transportation
A25: C1. Vehicle
A26: Avanza | B26: Day x Qty | C26: 450000 | D26: 3 | E26: =C26*D26 -> 1350000
A27: Innova | B27: Day x Qty | C27: 550000 | E27: =C27*D27 -> 0
A28: Toyota Hiace | B28: Day x Qty | C28: 1100000 | D28: =IF((($D$2>=4)*($D$2<=11))=1,4,0) -> 0 | E28: =C28*D28 -> 0
A29: Toyota Hiace Premio (4-6pax) | B29: Day x Qty | C29: 1300000 | E29: =C29*D29 -> 0
A30: Extra Luggage | B30: Day x Qty | C30: 2720000 | D30: =IF((($D$2>=10)*($D$2<=11))=1,1,0) -> 0 | E30: =C30*D30 -> 0
A31: C2. Parking and toll
A32: Probolingo | B32: No | C32: 200000 | D32: =IF((($D$2>=10)*($D$2<=11))=1,2,1) -> 1 | E32: =C32*D32 -> 200000
A33: Probolinggo + Malang | B33: No | C33: 300000 | E33: =C33*D33 -> 0
A34: D. Crews
A35: D1. In house
A36: Driver cum guide | B36: Day x Qty | C36: 250000 | D36: =IF((($D$2>=1)*($D$2<=3))=1,3,0) -> 3 | E36: =C36*D36 -> 750000
A37: Escort Guide | B37: Day x Qty | C37: 250000 | D37: =IF((($D$2>=4)*($D$2<=11))=1,3,0) -> 0 | E37: =C37*D37 -> 0
A38: Driver Only | B38: Day x Qty | C38: 200000 | E38: =C38*D38 -> 0
A39: E. Others
A40: E1. Miscelleneous
A41: Mineral Water | B41: Karton | C41: 50000 | D41: =ROUNDUP(D2*4*3/24,0) -> 2 | E41: =C41*D41 -> 100000
...

Sheet 4 Pax Safari
A1: Package Name | C1: Duration (Days) | D1: No of Pax
A2: 3D 2N Safari Park - Bromo - Surabaya | C2: 3 | D2: 4
A4: Description | B4: Unit | C4: Rate | D4: Qty | E4: Total
A5: A2. Bromo
A6: Joglo Kecombrang - Deluxe | B6: No | C6: 750000 | D6: 2 | E6: =C6*D6 -> 1500000
A7: Joglo Kecombrang - Family | B7: No | C7: 950000 | E7: =C7*D7 -> 0
A8: Joglo Kecombrang - Extra Bed | B8: No | C8: 300000 | E8: =C8*D8 -> 0
A9: A3. Taman Safari Prigen
A10: Baobab Safari Resort - Deluxe Safari View (Weekend) | B10: No | C10: 1700000 | D10: 2 | E10: =C10*D10 -> 3400000
A11: Baobab Safari Resort - Extra Bed | B11: No | C11: 500000 | E11: =C11*D11 -> 0
A12: B. Activities
A13: B2. Bromo
A14: Bromo - Ticket | B14: Pax | C14: 160000 | D14: =$D$2 -> 4 | E14: =C14*D14 -> 640000
A15: Bromo - Jeep | B15: Pax | C15: 500000 | D15: =ROUNDUP(D2/4,0) -> 1 | E15: =C15*D15 -> 500000
A16: B3. Madakaripura
A17: Motor + Ticket | B17: Pax | C17: 90000 | D17: =$D$2 -> 4 | E17: =C17*D17 -> 360000
A18: Madakaripura Local Guide | B18: No | C18: 100000 | D18: 1 | E18: =C18*D18 -> 100000
A19: B4. Taman Safari
A20: Breakfast With Giraffe (Max 4 pax / sesi) - Add on | B20: Pax | C20: 650000 | E20: =C20*D20 -> 0
A21: Surcharge Taman Safari Ticket | B21: No | C21: 150000 | D21: =$D$2 -> 4 | E21: =C21*D21 -> 600000
A22: Ticket Driver & Guide | B22: Pax | C22: 200000 | D22: 2 | E22: =C22*D22 -> 400000
A23: Parking | B23: No | C23: 10000 | D23: 1 | E23: =C23*D23 -> 10000
A24: C. Transportation
A25: C1. Vehicle
A26: Avanza | B26: Day x Qty | C26: 480000 | E26: =C26*D26 -> 0
A27: Innova | B27: Day x Qty | C27: 550000 | E27: =C27*D27 -> 0
A28: Toyota Hiace | B28: Day x Qty | C28: 1100000 | D28: =IF((($D$2>=4)*($D$2<=11))=1,3,0) -> 3 | E28: =C28*D28 -> 3300000
A29: Toyota Hiace Premio (4-6pax) | B29: Day x Qty | C29: 1300000 | E29: =C29*D29 -> 0
A30: Extra Luggage | B30: Day x Qty | C30: 2720000 | D30: =IF((($D$2>=10)*($D$2<=11))=1,1,0) -> 0 | E30: =C30*D30 -> 0
A31: C2. Parking and toll
A32: Probolingo | B32: No | C32: 200000 | D32: =IF((($D$2>=10)*($D$2<=11))=1,2,1) -> 1 | E32: =C32*D32 -> 200000
A33: Probolinggo + Malang | B33: No | C33: 300000 | E33: =C33*D33 -> 0
A34: D. Crews
A35: D1. In house
A36: Driver cum guide | B36: Day x Qty | C36: 250000 | D36: =IF((($D$2>=1)*($D$2<=3))=1,3,0) -> 0 | E36: =C36*D36 -> 0
A37: Escort Guide | B37: Day x Qty | C37: 250000 | D37: =IF((($D$2>=4)*($D$2<=11))=1,3,0) -> 3 | E37: =C37*D37 -> 750000
A38: Driver Only | B38: Day x Qty | C38: 200000 | E38: =C38*D38 -> 0
A39: E. Others
A40: E1. Miscelleneous
A41: Mineral Water | B41: Karton | C41: 50000 | D41: =ROUNDUP(D2*4*3/24,0) -> 2 | E41: =C41*D41 -> 100000
...

Sheet 5 Pax Safari
A1: Package Name | C1: Duration (Days) | D1: No of Pax
A2: 3D 2N Safari Park - Bromo - Surabaya | C2: 3 | D2: 5
A4: Description | B4: Unit | C4: Rate | D4: Qty | E4: Total
A5: A2. Bromo
A6: Joglo Kecombrang - Deluxe | B6: No | C6: 750000 | D6: 1 | E6: =C6*D6 -> 750000
A7: Joglo Kecombrang - Family | B7: No | C7: 950000 | D7: 1 | E7: =C7*D7 -> 950000
A8: Joglo Kecombrang - Extra Bed | B8: No | C8: 300000 | E8: =C8*D8 -> 0
A9: A3. Taman Safari Prigen
A10: Baobab Safari Resort - Deluxe Safari View (Weekend) | B10: No | C10: 1700000 | D10: 2 | E10: =C10*D10 -> 3400000
A11: Baobab Safari Resort - Extra Bed | B11: No | C11: 500000 | D11: 1 | E11: =C11*D11 -> 500000
A12: B. Activities
A13: B2. Bromo
A14: Bromo - Ticket | B14: Pax | C14: 160000 | D14: =$D$2 -> 5 | E14: =C14*D14 -> 800000
A15: Bromo - Jeep | B15: Pax | C15: 500000 | D15: =ROUNDUP(D2/4,0) -> 2 | E15: =C15*D15 -> 1000000
A16: B3. Madakaripura
A17: Motor + Ticket | B17: Pax | C17: 90000 | D17: =$D$2 -> 5 | E17: =C17*D17 -> 450000
A18: Madakaripura Local Guide | B18: No | C18: 100000 | D18: 1 | E18: =C18*D18 -> 100000
A19: B4. Taman Safari
A20: Breakfast With Giraffe (Max 4 pax / sesi) - Add on | B20: Pax | C20: 650000 | E20: =C20*D20 -> 0
A21: Surcharge Taman Safari Ticket | B21: No | C21: 150000 | D21: =$D$2 -> 5 | E21: =C21*D21 -> 750000
A22: Ticket Driver & Guide | B22: Pax | C22: 200000 | D22: 2 | E22: =C22*D22 -> 400000
A23: Parking | B23: No | C23: 10000 | D23: 1 | E23: =C23*D23 -> 10000
A24: C. Transportation
A25: C1. Vehicle
A26: Avanza | B26: Day x Qty | C26: 480000 | E26: =C26*D26 -> 0
A27: Innova | B27: Day x Qty | C27: 550000 | E27: =C27*D27 -> 0
A28: Toyota Hiace | B28: Day x Qty | C28: 1100000 | D28: =IF((($D$2>=4)*($D$2<=11))=1,3,0) -> 3 | E28: =C28*D28 -> 3300000
A29: Toyota Hiace Premio (4-6pax) | B29: Day x Qty | C29: 1300000 | E29: =C29*D29 -> 0
A30: Extra Luggage | B30: Day x Qty | C30: 2720000 | D30: =IF((($D$2>=10)*($D$2<=11))=1,1,0) -> 0 | E30: =C30*D30 -> 0
A31: C2. Parking and toll
A32: Probolingo | B32: No | C32: 200000 | D32: =IF((($D$2>=10)*($D$2<=11))=1,2,1) -> 1 | E32: =C32*D32 -> 200000
A33: Probolinggo + Malang | B33: No | C33: 300000 | E33: =C33*D33 -> 0
A34: D. Crews
A35: D1. In house
A36: Driver cum guide | B36: Day x Qty | C36: 250000 | D36: =IF((($D$2>=1)*($D$2<=3))=1,3,0) -> 0 | E36: =C36*D36 -> 0
A37: Escort Guide | B37: Day x Qty | C37: 250000 | D37: =IF((($D$2>=4)*($D$2<=11))=1,3,0) -> 3 | E37: =C37*D37 -> 750000
A38: Driver Only | B38: Day x Qty | C38: 200000 | E38: =C38*D38 -> 0
A39: E. Others
A40: E1. Miscelleneous
A41: Mineral Water | B41: Karton | C41: 50000 | D41: =ROUNDUP(D2*4*3/24,0) -> 3 | E41: =C41*D41 -> 150000
...

Sheet 6 Pax Safari
A1: Package Name | C1: Duration (Days) | D1: No of Pax
A2: 3D 2N Safari Park - Bromo - Surabaya | C2: 3 | D2: 6
A4: Description | B4: Unit | C4: Rate | D4: Qty | E4: Total
A5: A2. Bromo
A6: Joglo Kecombrang - Deluxe | B6: No | C6: 750000 | D6: 3 | E6: =C6*D6 -> 2250000
A7: Joglo Kecombrang - Family | B7: No | C7: 950000 | E7: =C7*D7 -> 0
A8: Joglo Kecombrang - Extra Bed | B8: No | C8: 300000 | E8: =C8*D8 -> 0
A9: A3. Taman Safari Prigen
A10: Baobab Safari Resort - Deluxe Safari View (Weekend) | B10: No | C10: 1700000 | D10: 3 | E10: =C10*D10 -> 5100000
A11: Baobab Safari Resort - Extra Bed | B11: No | C11: 500000 | E11: =C11*D11 -> 0
A12: B. Activities
A13: B2. Bromo
A14: Bromo - Ticket | B14: Pax | C14: 160000 | D14: =$D$2 -> 6 | E14: =C14*D14 -> 960000
A15: Bromo - Jeep | B15: Pax | C15: 500000 | D15: =ROUNDUP(D2/4,0) -> 2 | E15: =C15*D15 -> 1000000
A16: B3. Madakaripura
A17: Motor + Ticket | B17: Pax | C17: 90000 | D17: =$D$2 -> 6 | E17: =C17*D17 -> 540000
A18: Madakaripura Local Guide | B18: No | C18: 100000 | D18: 1 | E18: =C18*D18 -> 100000
A19: B4. Taman Safari
A20: Breakfast With Giraffe (Max 4 pax / sesi) - Add on | B20: Pax | C20: 650000 | E20: =C20*D20 -> 0
A21: Surcharge Taman Safari Ticket | B21: No | C21: 150000 | D21: =$D$2 -> 6 | E21: =C21*D21 -> 900000
A22: Ticket Driver & Guide | B22: Pax | C22: 200000 | D22: 2 | E22: =C22*D22 -> 400000
A23: Parking | B23: No | C23: 10000 | D23: 1 | E23: =C23*D23 -> 10000
A24: C. Transportation
A25: C1. Vehicle
A26: Avanza | B26: Day x Qty | C26: 480000 | E26: =C26*D26 -> 0
A27: Innova | B27: Day x Qty | C27: 550000 | E27: =C27*D27 -> 0
A28: Toyota Hiace | B28: Day x Qty | C28: 1100000 | D28: =IF((($D$2>=4)*($D$2<=11))=1,3,0) -> 3 | E28: =C28*D28 -> 3300000
A29: Toyota Hiace Premio (4-6pax) | B29: Day x Qty | C29: 1300000 | E29: =C29*D29 -> 0
A30: Extra Luggage | B30: Day x Qty | C30: 2720000 | D30: =IF((($D$2>=10)*($D$2<=11))=1,1,0) -> 0 | E30: =C30*D30 -> 0
A31: C2. Parking and toll
A32: Probolingo | B32: No | C32: 200000 | D32: =IF((($D$2>=10)*($D$2<=11))=1,2,1) -> 1 | E32: =C32*D32 -> 200000
A33: Probolinggo + Malang | B33: No | C33: 300000 | E33: =C33*D33 -> 0
A34: D. Crews
A35: D1. In house
A36: Driver cum guide | B36: Day x Qty | C36: 250000 | D36: =IF((($D$2>=1)*($D$2<=3))=1,3,0) -> 0 | E36: =C36*D36 -> 0
A37: Escort Guide | B37: Day x Qty | C37: 250000 | D37: =IF((($D$2>=4)*($D$2<=11))=1,3,0) -> 3 | E37: =C37*D37 -> 750000
A38: Driver Only | B38: Day x Qty | C38: 200000 | E38: =C38*D38 -> 0
A39: E. Others
A40: E1. Miscelleneous
A41: Mineral Water | B41: Karton | C41: 50000 | D41: =ROUNDUP(D2*4*3/24,0) -> 3 | E41: =C41*D41 -> 150000
...

Sheet 7 Pax Safari
A1: Package Name | C1: Duration (Days) | D1: No of Pax
A2: 3D 2N Safari Park - Bromo - Surabaya | C2: 3 | D2: 7
A4: Description | B4: Unit | C4: Rate | D4: Qty | E4: Total
A5: A2. Bromo
A6: Joglo Kecombrang - Deluxe | B6: No | C6: 750000 | D6: 2 | E6: =C6*D6 -> 1500000
A7: Joglo Kecombrang - Family | B7: No | C7: 950000 | D7: 1 | E7: =C7*D7 -> 950000
A8: Joglo Kecombrang - Extra Bed | B8: No | C8: 300000 | E8: =C8*D8 -> 0
A9: A3. Taman Safari Prigen
A10: Baobab Safari Resort - Deluxe Safari View (Weekend) | B10: No | C10: 1700000 | D10: 3 | E10: =C10*D10 -> 5100000
A11: Baobab Safari Resort - Extra Bed | B11: No | C11: 500000 | D11: 1 | E11: =C11*D11 -> 500000
A12: B. Activities
A13: B2. Bromo
A14: Bromo - Ticket | B14: Pax | C14: 160000 | D14: =$D$2 -> 7 | E14: =C14*D14 -> 1120000
A15: Bromo - Jeep | B15: Pax | C15: 500000 | D15: =ROUNDUP(D2/4,0) -> 2 | E15: =C15*D15 -> 1000000
A16: B3. Madakaripura
A17: Motor + Ticket | B17: Pax | C17: 90000 | D17: =$D$2 -> 7 | E17: =C17*D17 -> 630000
A18: Madakaripura Local Guide | B18: No | C18: 100000 | D18: 1 | E18: =C18*D18 -> 100000
A19: B4. Taman Safari
A20: Breakfast With Giraffe (Max 4 pax / sesi) - Add on | B20: Pax | C20: 650000 | E20: =C20*D20 -> 0
A21: Surcharge Taman Safari Ticket | B21: No | C21: 150000 | D21: =$D$2 -> 7 | E21: =C21*D21 -> 1050000
A22: Ticket Driver & Guide | B22: Pax | C22: 200000 | D22: 2 | E22: =C22*D22 -> 400000
A23: Parking | B23: No | C23: 10000 | D23: 1 | E23: =C23*D23 -> 10000
A24: C. Transportation
A25: C1. Vehicle
A26: Avanza | B26: Day x Qty | C26: 480000 | E26: =C26*D26 -> 0
A27: Innova | B27: Day x Qty | C27: 550000 | E27: =C27*D27 -> 0
A28: Toyota Hiace | B28: Day x Qty | C28: 1100000 | D28: =IF((($D$2>=4)*($D$2<=11))=1,3,0) -> 3 | E28: =C28*D28 -> 3300000
A29: Toyota Hiace Premio (4-6pax) | B29: Day x Qty | C29: 1300000 | E29: =C29*D29 -> 0
A30: Extra Luggage | B30: Day x Qty | C30: 2720000 | D30: =IF((($D$2>=10)*($D$2<=11))=1,1,0) -> 0 | E30: =C30*D30 -> 0
A31: C2. Parking and toll
A32: Probolingo | B32: No | C32: 200000 | D32: =IF((($D$2>=10)*($D$2<=11))=1,2,1) -> 1 | E32: =C32*D32 -> 200000
A33: Probolinggo + Malang | B33: No | C33: 300000 | E33: =C33*D33 -> 0
A34: D. Crews
A35: D1. In house
A36: Driver cum guide | B36: Day x Qty | C36: 250000 | D36: =IF((($D$2>=1)*($D$2<=3))=1,3,0) -> 0 | E36: =C36*D36 -> 0
A37: Escort Guide | B37: Day x Qty | C37: 250000 | D37: =IF((($D$2>=4)*($D$2<=11))=1,3,0) -> 3 | E37: =C37*D37 -> 750000
A38: Driver Only | B38: Day x Qty | C38: 200000 | E38: =C38*D38 -> 0
A39: E. Others
A40: E1. Miscelleneous
A41: Mineral Water | B41: Karton | C41: 50000 | D41: =ROUNDUP(D2*4*3/24,0) -> 4 | E41: =C41*D41 -> 200000
...

Sheet 8 Pax Safari
A1: Package Name | C1: Duration (Days) | D1: No of Pax
A2: 3D 2N Safari Park - Bromo - Surabaya | C2: 3 | D2: 8
A4: Description | B4: Unit | C4: Rate | D4: Qty | E4: Total
A5: A2. Bromo
A6: Joglo Kecombrang - Deluxe | B6: No | C6: 750000 | D6: 4 | E6: =C6*D6 -> 3000000
A7: Joglo Kecombrang - Family | B7: No | C7: 950000 | E7: =C7*D7 -> 0
A8: Joglo Kecombrang - Extra Bed | B8: No | C8: 300000 | E8: =C8*D8 -> 0
A9: A3. Taman Safari Prigen
A10: Baobab Safari Resort - Deluxe Safari View (Weekend) | B10: No | C10: 1700000 | D10: 4 | E10: =C10*D10 -> 6800000
A11: Baobab Safari Resort - Extra Bed | B11: No | C11: 500000 | E11: =C11*D11 -> 0
A12: B. Activities
A13: B2. Bromo
A14: Bromo - Ticket | B14: Pax | C14: 160000 | D14: =$D$2 -> 8 | E14: =C14*D14 -> 1280000
A15: Bromo - Jeep | B15: Pax | C15: 500000 | D15: =ROUNDUP(D2/4,0) -> 2 | E15: =C15*D15 -> 1000000
A16: B3. Madakaripura
A17: Motor + Ticket | B17: Pax | C17: 90000 | D17: =$D$2 -> 8 | E17: =C17*D17 -> 720000
A18: Madakaripura Local Guide | B18: No | C18: 100000 | D18: 1 | E18: =C18*D18 -> 100000
A19: B4. Taman Safari
A20: Breakfast With Giraffe (Max 4 pax / sesi) - Add on | B20: Pax | C20: 650000 | E20: =C20*D20 -> 0
A21: Surcharge Taman Safari Ticket | B21: No | C21: 150000 | D21: =$D$2 -> 8 | E21: =C21*D21 -> 1200000
A22: Ticket Driver & Guide | B22: Pax | C22: 200000 | D22: 2 | E22: =C22*D22 -> 400000
A23: Parking | B23: No | C23: 10000 | D23: 1 | E23: =C23*D23 -> 10000
A24: C. Transportation
A25: C1. Vehicle
A26: Avanza | B26: Day x Qty | C26: 480000 | E26: =C26*D26 -> 0
A27: Innova | B27: Day x Qty | C27: 550000 | E27: =C27*D27 -> 0
A28: Toyota Hiace | B28: Day x Qty | C28: 1100000 | D28: =IF((($D$2>=4)*($D$2<=11))=1,3,0) -> 3 | E28: =C28*D28 -> 3300000
A29: Toyota Hiace Premio (4-6pax) | B29: Day x Qty | C29: 1300000 | E29: =C29*D29 -> 0
A30: Extra Luggage | B30: Day x Qty | C30: 2720000 | D30: =IF((($D$2>=10)*($D$2<=11))=1,1,0) -> 0 | E30: =C30*D30 -> 0
A31: C2. Parking and toll
A32: Probolingo | B32: No | C32: 200000 | D32: =IF((($D$2>=10)*($D$2<=11))=1,2,1) -> 1 | E32: =C32*D32 -> 200000
A33: Probolinggo + Malang | B33: No | C33: 300000 | E33: =C33*D33 -> 0
A34: D. Crews
A35: D1. In house
A36: Driver cum guide | B36: Day x Qty | C36: 250000 | D36: =IF((($D$2>=1)*($D$2<=3))=1,3,0) -> 0 | E36: =C36*D36 -> 0
A37: Escort Guide | B37: Day x Qty | C37: 250000 | D37: =IF((($D$2>=4)*($D$2<=11))=1,3,0) -> 3 | E37: =C37*D37 -> 750000
A38: Driver Only | B38: Day x Qty | C38: 200000 | E38: =C38*D38 -> 0
A39: E. Others
A40: E1. Miscelleneous
A41: Mineral Water | B41: Karton | C41: 50000 | D41: =ROUNDUP(D2*4*3/24,0) -> 4 | E41: =C41*D41 -> 200000
...

Sheet 9 Pax Safari
A1: Package Name | C1: Duration (Days) | D1: No of Pax
A2: 3D 2N Safari Park - Bromo - Surabaya | C2: 3 | D2: 9
A4: Description | B4: Unit | C4: Rate | D4: Qty | E4: Total
A5: A2. Bromo
A6: Joglo Kecombrang - Deluxe | B6: No | C6: 750000 | D6: 3 | E6: =C6*D6 -> 2250000
A7: Joglo Kecombrang - Family | B7: No | C7: 950000 | D7: 1 | E7: =C7*D7 -> 950000
A8: Joglo Kecombrang - Extra Bed | B8: No | C8: 300000 | E8: =C8*D8 -> 0
A9: A3. Taman Safari Prigen
A10: Baobab Safari Resort - Deluxe Safari View (Weekend) | B10: No | C10: 1700000 | D10: 4 | E10: =C10*D10 -> 6800000
A11: Baobab Safari Resort - Extra Bed | B11: No | C11: 500000 | D11: 1 | E11: =C11*D11 -> 500000
A12: B. Activities
A13: B2. Bromo
A14: Bromo - Ticket | B14: Pax | C14: 160000 | D14: =$D$2 -> 9 | E14: =C14*D14 -> 1440000
A15: Bromo - Jeep | B15: Pax | C15: 500000 | D15: =ROUNDUP(D2/4,0) -> 3 | E15: =C15*D15 -> 1500000
A16: B3. Madakaripura
A17: Motor + Ticket | B17: Pax | C17: 90000 | D17: =$D$2 -> 9 | E17: =C17*D17 -> 810000
A18: Madakaripura Local Guide | B18: No | C18: 100000 | D18: 1 | E18: =C18*D18 -> 100000
A19: B4. Taman Safari
A20: Breakfast With Giraffe (Max 4 pax / sesi) - Add on | B20: Pax | C20: 650000 | E20: =C20*D20 -> 0
A21: Surcharge Taman Safari Ticket | B21: No | C21: 150000 | D21: =$D$2 -> 9 | E21: =C21*D21 -> 1350000
A22: Ticket Driver & Guide | B22: Pax | C22: 200000 | D22: 2 | E22: =C22*D22 -> 400000
A23: Parking | B23: No | C23: 10000 | D23: 1 | E23: =C23*D23 -> 10000
A24: C. Transportation
A25: C1. Vehicle
A26: Avanza | B26: Day x Qty | C26: 480000 | E26: =C26*D26 -> 0
A27: Innova | B27: Day x Qty | C27: 550000 | E27: =C27*D27 -> 0
A28: Toyota Hiace | B28: Day x Qty | C28: 1100000 | D28: =IF((($D$2>=4)*($D$2<=11))=1,3,0) -> 3 | E28: =C28*D28 -> 3300000
A29: Toyota Hiace Premio (4-6pax) | B29: Day x Qty | C29: 1300000 | E29: =C29*D29 -> 0
A30: Extra Luggage | B30: Day x Qty | C30: 2720000 | D30: =IF((($D$2>=10)*($D$2<=11))=1,1,0) -> 0 | E30: =C30*D30 -> 0
A31: C2. Parking and toll
A32: Probolingo | B32: No | C32: 200000 | D32: =IF((($D$2>=10)*($D$2<=11))=1,2,1) -> 1 | E32: =C32*D32 -> 200000
A33: Probolinggo + Malang | B33: No | C33: 300000 | E33: =C33*D33 -> 0
A34: D. Crews
A35: D1. In house
A36: Driver cum guide | B36: Day x Qty | C36: 250000 | D36: =IF((($D$2>=1)*($D$2<=3))=1,3,0) -> 0 | E36: =C36*D36 -> 0
A37: Escort Guide | B37: Day x Qty | C37: 250000 | D37: =IF((($D$2>=4)*($D$2<=11))=1,3,0) -> 3 | E37: =C37*D37 -> 750000
A38: Driver Only | B38: Day x Qty | C38: 200000 | E38: =C38*D38 -> 0
A39: E. Others
A40: E1. Miscelleneous
A41: Mineral Water | B41: Karton | C41: 50000 | D41: =ROUNDUP(D2*4*3/24,0) -> 5 | E41: =C41*D41 -> 250000
...

Sheet 10 Pax Safari
A1: Package Name | C1: Duration (Days) | D1: No of Pax
A2: 3D 2N Safari Park - Bromo - Surabaya | C2: 3 | D2: 10
A4: Description | B4: Unit | C4: Rate | D4: Qty | E4: Total
A5: A2. Bromo
A6: Joglo Kecombrang - Deluxe | B6: No | C6: 750000 | D6: 5 | E6: =C6*D6 -> 3750000
A7: Joglo Kecombrang - Family | B7: No | C7: 950000 | E7: =C7*D7 -> 0
A8: Joglo Kecombrang - Extra Bed | B8: No | C8: 300000 | E8: =C8*D8 -> 0
A9: A3. Taman Safari Prigen
A10: Baobab Safari Resort - Deluxe Safari View (Weekend) | B10: No | C10: 1700000 | D10: 5 | E10: =C10*D10 -> 8500000
A11: Baobab Safari Resort - Extra Bed | B11: No | C11: 500000 | E11: =C11*D11 -> 0
A12: B. Activities
A13: B2. Bromo
A14: Bromo - Ticket | B14: Pax | C14: 160000 | D14: =$D$2 -> 10 | E14: =C14*D14 -> 1600000
A15: Bromo - Jeep | B15: Pax | C15: 500000 | D15: =ROUNDUP(D2/4,0) -> 3 | E15: =C15*D15 -> 1500000
A16: B3. Madakaripura
A17: Motor + Ticket | B17: Pax | C17: 90000 | D17: =$D$2 -> 10 | E17: =C17*D17 -> 900000
A18: Madakaripura Local Guide | B18: No | C18: 100000 | D18: 1 | E18: =C18*D18 -> 100000
A19: B4. Taman Safari
A20: Breakfast With Giraffe (Max 4 pax / sesi) - Add on | B20: Pax | C20: 650000 | E20: =C20*D20 -> 0
A21: Surcharge Taman Safari Ticket | B21: No | C21: 150000 | D21: =$D$2 -> 10 | E21: =C21*D21 -> 1500000
A22: Ticket Driver & Guide | B22: Pax | C22: 200000 | D22: 3 | E22: =C22*D22 -> 600000
A23: Parking | B23: No | C23: 10000 | D23: 2 | E23: =C23*D23 -> 20000
A24: C. Transportation
A25: C1. Vehicle
A26: Avanza | B26: Day x Qty | C26: 480000 | E26: =C26*D26 -> 0
A27: Innova | B27: Day x Qty | C27: 550000 | E27: =C27*D27 -> 0
A28: Toyota Hiace | B28: Day x Qty | C28: 1100000 | D28: =IF((($D$2>=4)*($D$2<=11))=1,3,0) -> 3 | E28: =C28*D28 -> 3300000
A29: Toyota Hiace Premio (4-6pax) | B29: Day x Qty | C29: 1300000 | E29: =C29*D29 -> 0
A30: Extra Luggage | B30: Day x Qty | C30: 650000 | D30: 3 | E30: =C30*D30 -> 1950000 | J30: =I30*3 -> 0
A31: C2. Parking and toll
A32: Probolingo | B32: No | C32: 200000 | D32: =IF((($D$2>=10)*($D$2<=11))=1,2,1) -> 2 | E32: =C32*D32 -> 400000
A33: Probolinggo + Malang | B33: No | C33: 300000 | E33: =C33*D33 -> 0
A34: D. Crews
A35: D1. In house
A36: Driver cum guide | B36: Day x Qty | C36: 250000 | D36: =IF((($D$2>=1)*($D$2<=3))=1,3,0) -> 0 | E36: =C36*D36 -> 0
A37: Escort Guide | B37: Day x Qty | C37: 250000 | D37: =IF((($D$2>=4)*($D$2<=11))=1,3,0) -> 3 | E37: =C37*D37 -> 750000
A38: Driver Only | B38: Day x Qty | C38: 200000 | E38: =C38*D38 -> 0
A39: E. Others
A40: E1. Miscelleneous
A41: Mineral Water | B41: Karton | C41: 50000 | D41: =ROUNDUP(D2*4*3/24,0) -> 5 | E41: =C41*D41 -> 250000
...

Sheet 11 Pax Safari
A1: Package Name | C1: Duration (Days) | D1: No of Pax
A2: 3D 2N Safari Park - Bromo - Surabaya | C2: 3 | D2: 11
A4: Description | B4: Unit | C4: Rate | D4: Qty | E4: Total
A5: A2. Bromo
A6: Joglo Kecombrang - Deluxe | B6: No | C6: 750000 | D6: 4 | E6: =C6*D6 -> 3000000
A7: Joglo Kecombrang - Family | B7: No | C7: 950000 | D7: 1 | E7: =C7*D7 -> 950000
A8: Joglo Kecombrang - Extra Bed | B8: No | C8: 300000 | E8: =C8*D8 -> 0
A9: A3. Taman Safari Prigen
A10: Baobab Safari Resort - Deluxe Safari View (Weekend) | B10: No | C10: 1700000 | D10: 5 | E10: =C10*D10 -> 8500000
A11: Baobab Safari Resort - Extra Bed | B11: No | C11: 500000 | D11: 1 | E11: =C11*D11 -> 500000
A12: B. Activities
A13: B2. Bromo
A14: Bromo - Ticket | B14: Pax | C14: 160000 | D14: =$D$2 -> 11 | E14: =C14*D14 -> 1760000
A15: Bromo - Jeep | B15: Pax | C15: 500000 | D15: =ROUNDUP(D2/4,0) -> 3 | E15: =C15*D15 -> 1500000
A16: B3. Madakaripura
A17: Motor + Ticket | B17: Pax | C17: 90000 | D17: =$D$2 -> 11 | E17: =C17*D17 -> 990000
A18: Madakaripura Local Guide | B18: No | C18: 100000 | D18: 1 | E18: =C18*D18 -> 100000
A19: B4. Taman Safari
A20: Breakfast With Giraffe (Max 4 pax / sesi) - Add on | B20: Pax | C20: 650000 | E20: =C20*D20 -> 0
A21: Surcharge Taman Safari Ticket | B21: No | C21: 150000 | D21: =$D$2 -> 11 | E21: =C21*D21 -> 1650000
A22: Ticket Driver & Guide | B22: Pax | C22: 200000 | D22: 3 | E22: =C22*D22 -> 600000
A23: Parking | B23: No | C23: 10000 | D23: 2 | E23: =C23*D23 -> 20000
A24: C. Transportation
A25: C1. Vehicle
A26: Avanza | B26: Day x Qty | C26: 480000 | E26: =C26*D26 -> 0
A27: Innova | B27: Day x Qty | C27: 550000 | E27: =C27*D27 -> 0
A28: Toyota Hiace | B28: Day x Qty | C28: 1100000 | D28: =IF((($D$2>=4)*($D$2<=11))=1,3,0) -> 3 | E28: =C28*D28 -> 3300000
A29: Toyota Hiace Premio (4-6pax) | B29: Day x Qty | C29: 1300000 | E29: =C29*D29 -> 0
A30: Extra Luggage | B30: Day x Qty | C30: 650000 | D30: 3 | E30: =C30*D30 -> 1950000 | J30: =I30*3 -> 0
A31: C2. Parking and toll
A32: Probolingo | B32: No | C32: 200000 | D32: =IF((($D$2>=10)*($D$2<=11))=1,2,1) -> 2 | E32: =C32*D32 -> 400000
A33: Probolinggo + Malang | B33: No | C33: 300000 | E33: =C33*D33 -> 0
A34: D. Crews
A35: D1. In house
A36: Driver cum guide | B36: Day x Qty | C36: 250000 | D36: =IF((($D$2>=1)*($D$2<=3))=1,3,0) -> 0 | E36: =C36*D36 -> 0
A37: Escort Guide | B37: Day x Qty | C37: 250000 | D37: =IF((($D$2>=4)*($D$2<=11))=1,3,0) -> 3 | E37: =C37*D37 -> 750000
A38: Driver Only | B38: Day x Qty | C38: 200000 | E38: =C38*D38 -> 0
A39: E. Others
A40: E1. Miscelleneous
A41: Mineral Water | B41: Karton | C41: 50000 | D41: =ROUNDUP(D2*4*3/24,0) -> 6 | E41: =C41*D41 -> 300000
...

Sheet 12 Pax Safari
A1: Package Name | C1: Duration (Days) | D1: No of Pax
A2: 3D 2N Safari Park - Bromo - Surabaya | C2: 3 | D2: 12
A4: Description | B4: Unit | C4: Rate | D4: Qty | E4: Total
A5: A2. Bromo
A6: Joglo Kecombrang - Deluxe | B6: No | C6: 750000 | D6: 6 | E6: =C6*D6 -> 4500000
A7: Joglo Kecombrang - Family | B7: No | C7: 950000 | E7: =C7*D7 -> 0
A8: Joglo Kecombrang - Extra Bed | B8: No | C8: 300000 | E8: =C8*D8 -> 0
A9: A3. Taman Safari Prigen
A10: Baobab Safari Resort - Deluxe Safari View (Weekend) | B10: No | C10: 1700000 | D10: 6 | E10: =C10*D10 -> 10200000
A11: Baobab Safari Resort - Extra Bed | B11: No | C11: 500000 | E11: =C11*D11 -> 0
A12: B. Activities
A13: B2. Bromo
A14: Bromo - Ticket | B14: Pax | C14: 160000 | D14: =$D$2 -> 12 | E14: =C14*D14 -> 1920000
A15: Bromo - Jeep | B15: Pax | C15: 500000 | D15: =ROUNDUP(D2/4,0) -> 3 | E15: =C15*D15 -> 1500000
A16: B3. Madakaripura
A17: Motor + Ticket | B17: Pax | C17: 90000 | D17: =$D$2 -> 12 | E17: =C17*D17 -> 1080000
A18: Madakaripura Local Guide | B18: No | C18: 100000 | D18: 1 | E18: =C18*D18 -> 100000
A19: B4. Taman Safari
A20: Breakfast With Giraffe (Max 4 pax / sesi) - Add on | B20: Pax | C20: 650000 | E20: =C20*D20 -> 0
A21: Surcharge Taman Safari Ticket | B21: No | C21: 150000 | D21: =$D$2 -> 12 | E21: =C21*D21 -> 1800000
A22: Ticket Driver & Guide | B22: Pax | C22: 200000 | D22: 4 | E22: =C22*D22 -> 800000
A23: Parking | B23: No | C23: 10000 | D23: 2 | E23: =C23*D23 -> 20000
A24: C. Transportation
A25: C1. Vehicle
A26: Avanza | B26: Day x Qty | C26: 480000 | E26: =C26*D26 -> 0
A27: Innova | B27: Day x Qty | C27: 550000 | E27: =C27*D27 -> 0
A28: Toyota Hiace | B28: Day x Qty | C28: 1100000 | D28: 6 | E28: =C28*D28 -> 6600000
A29: Toyota Hiace Premio (4-6pax) | B29: Day x Qty | C29: 1300000 | E29: =C29*D29 -> 0
A30: Extra Luggage | B30: Day x Qty | C30: 650000 | E30: =C30*D30 -> 0 | J30: =I30*3 -> 0
A31: C2. Parking and toll
A32: Probolingo | B32: No | C32: 200000 | D32: 2 | E32: =C32*D32 -> 400000
A33: Probolinggo + Malang | B33: No | C33: 300000 | E33: =C33*D33 -> 0
A34: D. Crews
A35: D1. In house
A36: Driver cum guide | B36: Day x Qty | C36: 250000 | D36: =IF((($D$2>=1)*($D$2<=3))=1,3,0) -> 0 | E36: =C36*D36 -> 0
A37: Escort Guide | B37: Day x Qty | C37: 250000 | D37: 6 | E37: =C37*D37 -> 1500000
A38: Driver Only | B38: Day x Qty | C38: 200000 | E38: =C38*D38 -> 0
A39: E. Others
A40: E1. Miscelleneous
A41: Mineral Water | B41: Karton | C41: 50000 | D41: =ROUNDUP(D2*4*3/24,0) -> 6 | E41: =C41*D41 -> 300000
...
